2021-03-28 13:30:02.850 | WARNING  | shop.views:product_list:36 - some warning test <TranslatableQuerySet [<Category: coffee>, <Category: tea>, <Category: vegetables>, <Category: fruits>, <Category: some very long and crazy category just to test this crazy shit>]>
2021-03-28 13:30:02.858 | WARNING  | cart.cart:__init__:35 - cart init {'5': {'quantity': 11, 'price': '8.00'}}
2021-03-28 19:02:10.280 | ERROR    | cart.views:cart_detail:50 - An error has been caught in function 'cart_detail', process 'MainProcess' (18577), thread 'Thread-4' (139858563561216):
Traceback (most recent call last):
  File "/home/ubuntu/SuperShop/env/lib/python3.8/site-packages/redis/connection.py", line 552, in connect
    sock = self._connect()
  File "/home/ubuntu/SuperShop/env/lib/python3.8/site-packages/redis/connection.py", line 609, in _connect
    raise err
  File "/home/ubuntu/SuperShop/env/lib/python3.8/site-packages/redis/connection.py", line 597, in _connect
    sock.connect(socket_address)
ConnectionRefusedError: [Errno 111] Connection refused

During handling of the above exception, another exception occurred:

Traceback (most recent call last):
  File "/usr/lib/python3.8/threading.py", line 890, in _bootstrap
    self._bootstrap_inner()
  File "/usr/lib/python3.8/threading.py", line 932, in _bootstrap_inner
    self.run()
  File "/usr/lib/python3.8/threading.py", line 870, in run
    self._target(*self._args, **self._kwargs)
  File "/usr/lib/python3.8/socketserver.py", line 650, in process_request_thread
    self.finish_request(request, client_address)
  File "/usr/lib/python3.8/socketserver.py", line 360, in finish_request
    self.RequestHandlerClass(request, client_address, self)
  File "/usr/lib/python3.8/socketserver.py", line 720, in __init__
    self.handle()
  File "/home/ubuntu/SuperShop/env/lib/python3.8/site-packages/django/core/servers/basehttp.py", line 174, in handle
    self.handle_one_request()
  File "/home/ubuntu/SuperShop/env/lib/python3.8/site-packages/django/core/servers/basehttp.py", line 197, in handle_one_request
    handler.run(self.server.get_app())
  File "/usr/lib/python3.8/wsgiref/handlers.py", line 137, in run
    self.result = application(self.environ, self.start_response)
  File "/home/ubuntu/SuperShop/env/lib/python3.8/site-packages/django/contrib/staticfiles/handlers.py", line 68, in __call__
    return self.application(environ, start_response)
  File "/home/ubuntu/SuperShop/env/lib/python3.8/site-packages/django/core/handlers/wsgi.py", line 133, in __call__
    response = self.get_response(request)
  File "/home/ubuntu/SuperShop/env/lib/python3.8/site-packages/django/core/handlers/base.py", line 75, in get_response
    response = self._middleware_chain(request)
  File "/home/ubuntu/SuperShop/env/lib/python3.8/site-packages/django/core/handlers/exception.py", line 34, in inner
    response = get_response(request)
  File "/home/ubuntu/SuperShop/env/lib/python3.8/site-packages/django/utils/deprecation.py", line 94, in __call__
    response = response or self.get_response(request)
  File "/home/ubuntu/SuperShop/env/lib/python3.8/site-packages/django/core/handlers/exception.py", line 34, in inner
    response = get_response(request)
  File "/home/ubuntu/SuperShop/env/lib/python3.8/site-packages/django/utils/deprecation.py", line 94, in __call__
    response = response or self.get_response(request)
  File "/home/ubuntu/SuperShop/env/lib/python3.8/site-packages/django/core/handlers/exception.py", line 34, in inner
    response = get_response(request)
  File "/home/ubuntu/SuperShop/env/lib/python3.8/site-packages/django/utils/deprecation.py", line 94, in __call__
    response = response or self.get_response(request)
  File "/home/ubuntu/SuperShop/env/lib/python3.8/site-packages/django/core/handlers/exception.py", line 34, in inner
    response = get_response(request)
  File "/home/ubuntu/SuperShop/env/lib/python3.8/site-packages/django/utils/deprecation.py", line 94, in __call__
    response = response or self.get_response(request)
  File "/home/ubuntu/SuperShop/env/lib/python3.8/site-packages/django/core/handlers/exception.py", line 34, in inner
    response = get_response(request)
  File "/home/ubuntu/SuperShop/env/lib/python3.8/site-packages/django/utils/deprecation.py", line 94, in __call__
    response = response or self.get_response(request)
  File "/home/ubuntu/SuperShop/env/lib/python3.8/site-packages/django/core/handlers/exception.py", line 34, in inner
    response = get_response(request)
  File "/home/ubuntu/SuperShop/env/lib/python3.8/site-packages/django/utils/deprecation.py", line 94, in __call__
    response = response or self.get_response(request)
  File "/home/ubuntu/SuperShop/env/lib/python3.8/site-packages/django/core/handlers/exception.py", line 34, in inner
    response = get_response(request)
  File "/home/ubuntu/SuperShop/env/lib/python3.8/site-packages/django/utils/deprecation.py", line 94, in __call__
    response = response or self.get_response(request)
  File "/home/ubuntu/SuperShop/env/lib/python3.8/site-packages/django/core/handlers/exception.py", line 34, in inner
    response = get_response(request)
  File "/home/ubuntu/SuperShop/env/lib/python3.8/site-packages/django/utils/deprecation.py", line 94, in __call__
    response = response or self.get_response(request)
  File "/home/ubuntu/SuperShop/env/lib/python3.8/site-packages/django/core/handlers/exception.py", line 34, in inner
    response = get_response(request)
  File "/home/ubuntu/SuperShop/env/lib/python3.8/site-packages/django/core/handlers/base.py", line 113, in _get_response
    response = wrapped_callback(request, *callback_args, **callback_kwargs)
> File "/home/ubuntu/SuperShop/cart/views.py", line 50, in cart_detail
    recommended_products = r.suggest_products_for(cart_products,
  File "/home/ubuntu/SuperShop/shop/recommender.py", line 41, in suggest_products_for
    suggestions = r.zrange(
  File "/home/ubuntu/SuperShop/env/lib/python3.8/site-packages/redis/client.py", line 2757, in zrange
    return self.zrevrange(name, start, end, withscores,
  File "/home/ubuntu/SuperShop/env/lib/python3.8/site-packages/redis/client.py", line 2884, in zrevrange
    return self.execute_command(*pieces, **options)
  File "/home/ubuntu/SuperShop/env/lib/python3.8/site-packages/redis/client.py", line 875, in execute_command
    conn = self.connection or pool.get_connection(command_name, **options)
  File "/home/ubuntu/SuperShop/env/lib/python3.8/site-packages/redis/connection.py", line 1185, in get_connection
    connection.connect()
  File "/home/ubuntu/SuperShop/env/lib/python3.8/site-packages/redis/connection.py", line 557, in connect
    raise ConnectionError(self._error_message(e))
redis.exceptions.ConnectionError: Error 111 connecting to localhost:6379. Connection refused.
2021-03-29 07:40:53.624 | ERROR    | cart.views:cart_detail:50 - An error has been caught in function 'cart_detail', process 'MainProcess' (2185), thread 'Thread-5' (139747288672000):
Traceback (most recent call last):
  File "/home/ubuntu/SuperShop/env/lib/python3.8/site-packages/redis/connection.py", line 552, in connect
    sock = self._connect()
  File "/home/ubuntu/SuperShop/env/lib/python3.8/site-packages/redis/connection.py", line 609, in _connect
    raise err
  File "/home/ubuntu/SuperShop/env/lib/python3.8/site-packages/redis/connection.py", line 597, in _connect
    sock.connect(socket_address)
ConnectionRefusedError: [Errno 111] Connection refused

During handling of the above exception, another exception occurred:

Traceback (most recent call last):
  File "/usr/lib/python3.8/threading.py", line 890, in _bootstrap
    self._bootstrap_inner()
  File "/usr/lib/python3.8/threading.py", line 932, in _bootstrap_inner
    self.run()
  File "/usr/lib/python3.8/threading.py", line 870, in run
    self._target(*self._args, **self._kwargs)
  File "/usr/lib/python3.8/socketserver.py", line 650, in process_request_thread
    self.finish_request(request, client_address)
  File "/usr/lib/python3.8/socketserver.py", line 360, in finish_request
    self.RequestHandlerClass(request, client_address, self)
  File "/usr/lib/python3.8/socketserver.py", line 720, in __init__
    self.handle()
  File "/home/ubuntu/SuperShop/env/lib/python3.8/site-packages/django/core/servers/basehttp.py", line 174, in handle
    self.handle_one_request()
  File "/home/ubuntu/SuperShop/env/lib/python3.8/site-packages/django/core/servers/basehttp.py", line 197, in handle_one_request
    handler.run(self.server.get_app())
  File "/usr/lib/python3.8/wsgiref/handlers.py", line 137, in run
    self.result = application(self.environ, self.start_response)
  File "/home/ubuntu/SuperShop/env/lib/python3.8/site-packages/django/contrib/staticfiles/handlers.py", line 68, in __call__
    return self.application(environ, start_response)
  File "/home/ubuntu/SuperShop/env/lib/python3.8/site-packages/django/core/handlers/wsgi.py", line 133, in __call__
    response = self.get_response(request)
  File "/home/ubuntu/SuperShop/env/lib/python3.8/site-packages/django/core/handlers/base.py", line 75, in get_response
    response = self._middleware_chain(request)
  File "/home/ubuntu/SuperShop/env/lib/python3.8/site-packages/django/core/handlers/exception.py", line 34, in inner
    response = get_response(request)
  File "/home/ubuntu/SuperShop/env/lib/python3.8/site-packages/django/utils/deprecation.py", line 94, in __call__
    response = response or self.get_response(request)
  File "/home/ubuntu/SuperShop/env/lib/python3.8/site-packages/django/core/handlers/exception.py", line 34, in inner
    response = get_response(request)
  File "/home/ubuntu/SuperShop/env/lib/python3.8/site-packages/django/utils/deprecation.py", line 94, in __call__
    response = response or self.get_response(request)
  File "/home/ubuntu/SuperShop/env/lib/python3.8/site-packages/django/core/handlers/exception.py", line 34, in inner
    response = get_response(request)
  File "/home/ubuntu/SuperShop/env/lib/python3.8/site-packages/django/utils/deprecation.py", line 94, in __call__
    response = response or self.get_response(request)
  File "/home/ubuntu/SuperShop/env/lib/python3.8/site-packages/django/core/handlers/exception.py", line 34, in inner
    response = get_response(request)
  File "/home/ubuntu/SuperShop/env/lib/python3.8/site-packages/django/utils/deprecation.py", line 94, in __call__
    response = response or self.get_response(request)
  File "/home/ubuntu/SuperShop/env/lib/python3.8/site-packages/django/core/handlers/exception.py", line 34, in inner
    response = get_response(request)
  File "/home/ubuntu/SuperShop/env/lib/python3.8/site-packages/django/utils/deprecation.py", line 94, in __call__
    response = response or self.get_response(request)
  File "/home/ubuntu/SuperShop/env/lib/python3.8/site-packages/django/core/handlers/exception.py", line 34, in inner
    response = get_response(request)
  File "/home/ubuntu/SuperShop/env/lib/python3.8/site-packages/django/utils/deprecation.py", line 94, in __call__
    response = response or self.get_response(request)
  File "/home/ubuntu/SuperShop/env/lib/python3.8/site-packages/django/core/handlers/exception.py", line 34, in inner
    response = get_response(request)
  File "/home/ubuntu/SuperShop/env/lib/python3.8/site-packages/django/utils/deprecation.py", line 94, in __call__
    response = response or self.get_response(request)
  File "/home/ubuntu/SuperShop/env/lib/python3.8/site-packages/django/core/handlers/exception.py", line 34, in inner
    response = get_response(request)
  File "/home/ubuntu/SuperShop/env/lib/python3.8/site-packages/django/utils/deprecation.py", line 94, in __call__
    response = response or self.get_response(request)
  File "/home/ubuntu/SuperShop/env/lib/python3.8/site-packages/django/core/handlers/exception.py", line 34, in inner
    response = get_response(request)
  File "/home/ubuntu/SuperShop/env/lib/python3.8/site-packages/django/core/handlers/base.py", line 113, in _get_response
    response = wrapped_callback(request, *callback_args, **callback_kwargs)
> File "/home/ubuntu/SuperShop/cart/views.py", line 50, in cart_detail
    recommended_products = r.suggest_products_for(cart_products,
  File "/home/ubuntu/SuperShop/shop/recommender.py", line 41, in suggest_products_for
    suggestions = r.zrange(
  File "/home/ubuntu/SuperShop/env/lib/python3.8/site-packages/redis/client.py", line 2757, in zrange
    return self.zrevrange(name, start, end, withscores,
  File "/home/ubuntu/SuperShop/env/lib/python3.8/site-packages/redis/client.py", line 2884, in zrevrange
    return self.execute_command(*pieces, **options)
  File "/home/ubuntu/SuperShop/env/lib/python3.8/site-packages/redis/client.py", line 875, in execute_command
    conn = self.connection or pool.get_connection(command_name, **options)
  File "/home/ubuntu/SuperShop/env/lib/python3.8/site-packages/redis/connection.py", line 1185, in get_connection
    connection.connect()
  File "/home/ubuntu/SuperShop/env/lib/python3.8/site-packages/redis/connection.py", line 557, in connect
    raise ConnectionError(self._error_message(e))
redis.exceptions.ConnectionError: Error 111 connecting to localhost:6379. Connection refused.
2021-03-29 07:46:27.253 | ERROR    | cart.views:cart_detail:50 - An error has been caught in function 'cart_detail', process 'MainProcess' (2185), thread 'Thread-13' (139747279755008):
Traceback (most recent call last):
  File "/home/ubuntu/SuperShop/env/lib/python3.8/site-packages/redis/connection.py", line 552, in connect
    sock = self._connect()
  File "/home/ubuntu/SuperShop/env/lib/python3.8/site-packages/redis/connection.py", line 609, in _connect
    raise err
  File "/home/ubuntu/SuperShop/env/lib/python3.8/site-packages/redis/connection.py", line 597, in _connect
    sock.connect(socket_address)
ConnectionRefusedError: [Errno 111] Connection refused

During handling of the above exception, another exception occurred:

Traceback (most recent call last):
  File "/usr/lib/python3.8/threading.py", line 890, in _bootstrap
    self._bootstrap_inner()
  File "/usr/lib/python3.8/threading.py", line 932, in _bootstrap_inner
    self.run()
  File "/usr/lib/python3.8/threading.py", line 870, in run
    self._target(*self._args, **self._kwargs)
  File "/usr/lib/python3.8/socketserver.py", line 650, in process_request_thread
    self.finish_request(request, client_address)
  File "/usr/lib/python3.8/socketserver.py", line 360, in finish_request
    self.RequestHandlerClass(request, client_address, self)
  File "/usr/lib/python3.8/socketserver.py", line 720, in __init__
    self.handle()
  File "/home/ubuntu/SuperShop/env/lib/python3.8/site-packages/django/core/servers/basehttp.py", line 172, in handle
    self.handle_one_request()
  File "/home/ubuntu/SuperShop/env/lib/python3.8/site-packages/django/core/servers/basehttp.py", line 197, in handle_one_request
    handler.run(self.server.get_app())
  File "/usr/lib/python3.8/wsgiref/handlers.py", line 137, in run
    self.result = application(self.environ, self.start_response)
  File "/home/ubuntu/SuperShop/env/lib/python3.8/site-packages/django/contrib/staticfiles/handlers.py", line 68, in __call__
    return self.application(environ, start_response)
  File "/home/ubuntu/SuperShop/env/lib/python3.8/site-packages/django/core/handlers/wsgi.py", line 133, in __call__
    response = self.get_response(request)
  File "/home/ubuntu/SuperShop/env/lib/python3.8/site-packages/django/core/handlers/base.py", line 75, in get_response
    response = self._middleware_chain(request)
  File "/home/ubuntu/SuperShop/env/lib/python3.8/site-packages/django/core/handlers/exception.py", line 34, in inner
    response = get_response(request)
  File "/home/ubuntu/SuperShop/env/lib/python3.8/site-packages/django/utils/deprecation.py", line 94, in __call__
    response = response or self.get_response(request)
  File "/home/ubuntu/SuperShop/env/lib/python3.8/site-packages/django/core/handlers/exception.py", line 34, in inner
    response = get_response(request)
  File "/home/ubuntu/SuperShop/env/lib/python3.8/site-packages/django/utils/deprecation.py", line 94, in __call__
    response = response or self.get_response(request)
  File "/home/ubuntu/SuperShop/env/lib/python3.8/site-packages/django/core/handlers/exception.py", line 34, in inner
    response = get_response(request)
  File "/home/ubuntu/SuperShop/env/lib/python3.8/site-packages/django/utils/deprecation.py", line 94, in __call__
    response = response or self.get_response(request)
  File "/home/ubuntu/SuperShop/env/lib/python3.8/site-packages/django/core/handlers/exception.py", line 34, in inner
    response = get_response(request)
  File "/home/ubuntu/SuperShop/env/lib/python3.8/site-packages/django/utils/deprecation.py", line 94, in __call__
    response = response or self.get_response(request)
  File "/home/ubuntu/SuperShop/env/lib/python3.8/site-packages/django/core/handlers/exception.py", line 34, in inner
    response = get_response(request)
  File "/home/ubuntu/SuperShop/env/lib/python3.8/site-packages/django/utils/deprecation.py", line 94, in __call__
    response = response or self.get_response(request)
  File "/home/ubuntu/SuperShop/env/lib/python3.8/site-packages/django/core/handlers/exception.py", line 34, in inner
    response = get_response(request)
  File "/home/ubuntu/SuperShop/env/lib/python3.8/site-packages/django/utils/deprecation.py", line 94, in __call__
    response = response or self.get_response(request)
  File "/home/ubuntu/SuperShop/env/lib/python3.8/site-packages/django/core/handlers/exception.py", line 34, in inner
    response = get_response(request)
  File "/home/ubuntu/SuperShop/env/lib/python3.8/site-packages/django/utils/deprecation.py", line 94, in __call__
    response = response or self.get_response(request)
  File "/home/ubuntu/SuperShop/env/lib/python3.8/site-packages/django/core/handlers/exception.py", line 34, in inner
    response = get_response(request)
  File "/home/ubuntu/SuperShop/env/lib/python3.8/site-packages/django/utils/deprecation.py", line 94, in __call__
    response = response or self.get_response(request)
  File "/home/ubuntu/SuperShop/env/lib/python3.8/site-packages/django/core/handlers/exception.py", line 34, in inner
    response = get_response(request)
  File "/home/ubuntu/SuperShop/env/lib/python3.8/site-packages/django/core/handlers/base.py", line 113, in _get_response
    response = wrapped_callback(request, *callback_args, **callback_kwargs)
> File "/home/ubuntu/SuperShop/cart/views.py", line 50, in cart_detail
    recommended_products = r.suggest_products_for(cart_products,
  File "/home/ubuntu/SuperShop/shop/recommender.py", line 41, in suggest_products_for
    suggestions = r.zrange(
  File "/home/ubuntu/SuperShop/env/lib/python3.8/site-packages/redis/client.py", line 2757, in zrange
    return self.zrevrange(name, start, end, withscores,
  File "/home/ubuntu/SuperShop/env/lib/python3.8/site-packages/redis/client.py", line 2884, in zrevrange
    return self.execute_command(*pieces, **options)
  File "/home/ubuntu/SuperShop/env/lib/python3.8/site-packages/redis/client.py", line 875, in execute_command
    conn = self.connection or pool.get_connection(command_name, **options)
  File "/home/ubuntu/SuperShop/env/lib/python3.8/site-packages/redis/connection.py", line 1185, in get_connection
    connection.connect()
  File "/home/ubuntu/SuperShop/env/lib/python3.8/site-packages/redis/connection.py", line 557, in connect
    raise ConnectionError(self._error_message(e))
redis.exceptions.ConnectionError: Error 111 connecting to localhost:6379. Connection refused.
2021-03-29 07:58:36.456 | ERROR    | cart.views:cart_detail:50 - An error has been caught in function 'cart_detail', process 'MainProcess' (2185), thread 'Thread-16' (139747297064704):
Traceback (most recent call last):
  File "/home/ubuntu/SuperShop/env/lib/python3.8/site-packages/redis/connection.py", line 552, in connect
    sock = self._connect()
  File "/home/ubuntu/SuperShop/env/lib/python3.8/site-packages/redis/connection.py", line 609, in _connect
    raise err
  File "/home/ubuntu/SuperShop/env/lib/python3.8/site-packages/redis/connection.py", line 597, in _connect
    sock.connect(socket_address)
ConnectionRefusedError: [Errno 111] Connection refused

During handling of the above exception, another exception occurred:

Traceback (most recent call last):
  File "/usr/lib/python3.8/threading.py", line 890, in _bootstrap
    self._bootstrap_inner()
  File "/usr/lib/python3.8/threading.py", line 932, in _bootstrap_inner
    self.run()
  File "/usr/lib/python3.8/threading.py", line 870, in run
    self._target(*self._args, **self._kwargs)
  File "/usr/lib/python3.8/socketserver.py", line 650, in process_request_thread
    self.finish_request(request, client_address)
  File "/usr/lib/python3.8/socketserver.py", line 360, in finish_request
    self.RequestHandlerClass(request, client_address, self)
  File "/usr/lib/python3.8/socketserver.py", line 720, in __init__
    self.handle()
  File "/home/ubuntu/SuperShop/env/lib/python3.8/site-packages/django/core/servers/basehttp.py", line 172, in handle
    self.handle_one_request()
  File "/home/ubuntu/SuperShop/env/lib/python3.8/site-packages/django/core/servers/basehttp.py", line 197, in handle_one_request
    handler.run(self.server.get_app())
  File "/usr/lib/python3.8/wsgiref/handlers.py", line 137, in run
    self.result = application(self.environ, self.start_response)
  File "/home/ubuntu/SuperShop/env/lib/python3.8/site-packages/django/contrib/staticfiles/handlers.py", line 68, in __call__
    return self.application(environ, start_response)
  File "/home/ubuntu/SuperShop/env/lib/python3.8/site-packages/django/core/handlers/wsgi.py", line 133, in __call__
    response = self.get_response(request)
  File "/home/ubuntu/SuperShop/env/lib/python3.8/site-packages/django/core/handlers/base.py", line 75, in get_response
    response = self._middleware_chain(request)
  File "/home/ubuntu/SuperShop/env/lib/python3.8/site-packages/django/core/handlers/exception.py", line 34, in inner
    response = get_response(request)
  File "/home/ubuntu/SuperShop/env/lib/python3.8/site-packages/django/utils/deprecation.py", line 94, in __call__
    response = response or self.get_response(request)
  File "/home/ubuntu/SuperShop/env/lib/python3.8/site-packages/django/core/handlers/exception.py", line 34, in inner
    response = get_response(request)
  File "/home/ubuntu/SuperShop/env/lib/python3.8/site-packages/django/utils/deprecation.py", line 94, in __call__
    response = response or self.get_response(request)
  File "/home/ubuntu/SuperShop/env/lib/python3.8/site-packages/django/core/handlers/exception.py", line 34, in inner
    response = get_response(request)
  File "/home/ubuntu/SuperShop/env/lib/python3.8/site-packages/django/utils/deprecation.py", line 94, in __call__
    response = response or self.get_response(request)
  File "/home/ubuntu/SuperShop/env/lib/python3.8/site-packages/django/core/handlers/exception.py", line 34, in inner
    response = get_response(request)
  File "/home/ubuntu/SuperShop/env/lib/python3.8/site-packages/django/utils/deprecation.py", line 94, in __call__
    response = response or self.get_response(request)
  File "/home/ubuntu/SuperShop/env/lib/python3.8/site-packages/django/core/handlers/exception.py", line 34, in inner
    response = get_response(request)
  File "/home/ubuntu/SuperShop/env/lib/python3.8/site-packages/django/utils/deprecation.py", line 94, in __call__
    response = response or self.get_response(request)
  File "/home/ubuntu/SuperShop/env/lib/python3.8/site-packages/django/core/handlers/exception.py", line 34, in inner
    response = get_response(request)
  File "/home/ubuntu/SuperShop/env/lib/python3.8/site-packages/django/utils/deprecation.py", line 94, in __call__
    response = response or self.get_response(request)
  File "/home/ubuntu/SuperShop/env/lib/python3.8/site-packages/django/core/handlers/exception.py", line 34, in inner
    response = get_response(request)
  File "/home/ubuntu/SuperShop/env/lib/python3.8/site-packages/django/utils/deprecation.py", line 94, in __call__
    response = response or self.get_response(request)
  File "/home/ubuntu/SuperShop/env/lib/python3.8/site-packages/django/core/handlers/exception.py", line 34, in inner
    response = get_response(request)
  File "/home/ubuntu/SuperShop/env/lib/python3.8/site-packages/django/utils/deprecation.py", line 94, in __call__
    response = response or self.get_response(request)
  File "/home/ubuntu/SuperShop/env/lib/python3.8/site-packages/django/core/handlers/exception.py", line 34, in inner
    response = get_response(request)
  File "/home/ubuntu/SuperShop/env/lib/python3.8/site-packages/django/core/handlers/base.py", line 113, in _get_response
    response = wrapped_callback(request, *callback_args, **callback_kwargs)
> File "/home/ubuntu/SuperShop/cart/views.py", line 50, in cart_detail
    recommended_products = r.suggest_products_for(cart_products,
  File "/home/ubuntu/SuperShop/shop/recommender.py", line 41, in suggest_products_for
    suggestions = r.zrange(
  File "/home/ubuntu/SuperShop/env/lib/python3.8/site-packages/redis/client.py", line 2757, in zrange
    return self.zrevrange(name, start, end, withscores,
  File "/home/ubuntu/SuperShop/env/lib/python3.8/site-packages/redis/client.py", line 2884, in zrevrange
    return self.execute_command(*pieces, **options)
  File "/home/ubuntu/SuperShop/env/lib/python3.8/site-packages/redis/client.py", line 875, in execute_command
    conn = self.connection or pool.get_connection(command_name, **options)
  File "/home/ubuntu/SuperShop/env/lib/python3.8/site-packages/redis/connection.py", line 1185, in get_connection
    connection.connect()
  File "/home/ubuntu/SuperShop/env/lib/python3.8/site-packages/redis/connection.py", line 557, in connect
    raise ConnectionError(self._error_message(e))
redis.exceptions.ConnectionError: Error 111 connecting to localhost:6379. Connection refused.
2021-03-29 08:25:03.240 | ERROR    | cart.views:cart_detail:50 - An error has been caught in function 'cart_detail', process 'MainProcess' (2185), thread 'Thread-19' (139747279755008):
Traceback (most recent call last):
  File "/home/ubuntu/SuperShop/env/lib/python3.8/site-packages/redis/connection.py", line 552, in connect
    sock = self._connect()
  File "/home/ubuntu/SuperShop/env/lib/python3.8/site-packages/redis/connection.py", line 609, in _connect
    raise err
  File "/home/ubuntu/SuperShop/env/lib/python3.8/site-packages/redis/connection.py", line 597, in _connect
    sock.connect(socket_address)
ConnectionRefusedError: [Errno 111] Connection refused

During handling of the above exception, another exception occurred:

Traceback (most recent call last):
  File "/usr/lib/python3.8/threading.py", line 890, in _bootstrap
    self._bootstrap_inner()
  File "/usr/lib/python3.8/threading.py", line 932, in _bootstrap_inner
    self.run()
  File "/usr/lib/python3.8/threading.py", line 870, in run
    self._target(*self._args, **self._kwargs)
  File "/usr/lib/python3.8/socketserver.py", line 650, in process_request_thread
    self.finish_request(request, client_address)
  File "/usr/lib/python3.8/socketserver.py", line 360, in finish_request
    self.RequestHandlerClass(request, client_address, self)
  File "/usr/lib/python3.8/socketserver.py", line 720, in __init__
    self.handle()
  File "/home/ubuntu/SuperShop/env/lib/python3.8/site-packages/django/core/servers/basehttp.py", line 172, in handle
    self.handle_one_request()
  File "/home/ubuntu/SuperShop/env/lib/python3.8/site-packages/django/core/servers/basehttp.py", line 197, in handle_one_request
    handler.run(self.server.get_app())
  File "/usr/lib/python3.8/wsgiref/handlers.py", line 137, in run
    self.result = application(self.environ, self.start_response)
  File "/home/ubuntu/SuperShop/env/lib/python3.8/site-packages/django/contrib/staticfiles/handlers.py", line 68, in __call__
    return self.application(environ, start_response)
  File "/home/ubuntu/SuperShop/env/lib/python3.8/site-packages/django/core/handlers/wsgi.py", line 133, in __call__
    response = self.get_response(request)
  File "/home/ubuntu/SuperShop/env/lib/python3.8/site-packages/django/core/handlers/base.py", line 75, in get_response
    response = self._middleware_chain(request)
  File "/home/ubuntu/SuperShop/env/lib/python3.8/site-packages/django/core/handlers/exception.py", line 34, in inner
    response = get_response(request)
  File "/home/ubuntu/SuperShop/env/lib/python3.8/site-packages/django/utils/deprecation.py", line 94, in __call__
    response = response or self.get_response(request)
  File "/home/ubuntu/SuperShop/env/lib/python3.8/site-packages/django/core/handlers/exception.py", line 34, in inner
    response = get_response(request)
  File "/home/ubuntu/SuperShop/env/lib/python3.8/site-packages/django/utils/deprecation.py", line 94, in __call__
    response = response or self.get_response(request)
  File "/home/ubuntu/SuperShop/env/lib/python3.8/site-packages/django/core/handlers/exception.py", line 34, in inner
    response = get_response(request)
  File "/home/ubuntu/SuperShop/env/lib/python3.8/site-packages/django/utils/deprecation.py", line 94, in __call__
    response = response or self.get_response(request)
  File "/home/ubuntu/SuperShop/env/lib/python3.8/site-packages/django/core/handlers/exception.py", line 34, in inner
    response = get_response(request)
  File "/home/ubuntu/SuperShop/env/lib/python3.8/site-packages/django/utils/deprecation.py", line 94, in __call__
    response = response or self.get_response(request)
  File "/home/ubuntu/SuperShop/env/lib/python3.8/site-packages/django/core/handlers/exception.py", line 34, in inner
    response = get_response(request)
  File "/home/ubuntu/SuperShop/env/lib/python3.8/site-packages/django/utils/deprecation.py", line 94, in __call__
    response = response or self.get_response(request)
  File "/home/ubuntu/SuperShop/env/lib/python3.8/site-packages/django/core/handlers/exception.py", line 34, in inner
    response = get_response(request)
  File "/home/ubuntu/SuperShop/env/lib/python3.8/site-packages/django/utils/deprecation.py", line 94, in __call__
    response = response or self.get_response(request)
  File "/home/ubuntu/SuperShop/env/lib/python3.8/site-packages/django/core/handlers/exception.py", line 34, in inner
    response = get_response(request)
  File "/home/ubuntu/SuperShop/env/lib/python3.8/site-packages/django/utils/deprecation.py", line 94, in __call__
    response = response or self.get_response(request)
  File "/home/ubuntu/SuperShop/env/lib/python3.8/site-packages/django/core/handlers/exception.py", line 34, in inner
    response = get_response(request)
  File "/home/ubuntu/SuperShop/env/lib/python3.8/site-packages/django/utils/deprecation.py", line 94, in __call__
    response = response or self.get_response(request)
  File "/home/ubuntu/SuperShop/env/lib/python3.8/site-packages/django/core/handlers/exception.py", line 34, in inner
    response = get_response(request)
  File "/home/ubuntu/SuperShop/env/lib/python3.8/site-packages/django/core/handlers/base.py", line 113, in _get_response
    response = wrapped_callback(request, *callback_args, **callback_kwargs)
> File "/home/ubuntu/SuperShop/cart/views.py", line 50, in cart_detail
    recommended_products = r.suggest_products_for(cart_products,
  File "/home/ubuntu/SuperShop/shop/recommender.py", line 41, in suggest_products_for
    suggestions = r.zrange(
  File "/home/ubuntu/SuperShop/env/lib/python3.8/site-packages/redis/client.py", line 2757, in zrange
    return self.zrevrange(name, start, end, withscores,
  File "/home/ubuntu/SuperShop/env/lib/python3.8/site-packages/redis/client.py", line 2884, in zrevrange
    return self.execute_command(*pieces, **options)
  File "/home/ubuntu/SuperShop/env/lib/python3.8/site-packages/redis/client.py", line 875, in execute_command
    conn = self.connection or pool.get_connection(command_name, **options)
  File "/home/ubuntu/SuperShop/env/lib/python3.8/site-packages/redis/connection.py", line 1185, in get_connection
    connection.connect()
  File "/home/ubuntu/SuperShop/env/lib/python3.8/site-packages/redis/connection.py", line 557, in connect
    raise ConnectionError(self._error_message(e))
redis.exceptions.ConnectionError: Error 111 connecting to localhost:6379. Connection refused.
2021-03-29 08:31:33.120 | ERROR    | cart.views:cart_detail:50 - An error has been caught in function 'cart_detail', process 'MainProcess' (2185), thread 'Thread-22' (139747450226432):
Traceback (most recent call last):
  File "/home/ubuntu/SuperShop/env/lib/python3.8/site-packages/redis/connection.py", line 552, in connect
    sock = self._connect()
  File "/home/ubuntu/SuperShop/env/lib/python3.8/site-packages/redis/connection.py", line 609, in _connect
    raise err
  File "/home/ubuntu/SuperShop/env/lib/python3.8/site-packages/redis/connection.py", line 597, in _connect
    sock.connect(socket_address)
ConnectionRefusedError: [Errno 111] Connection refused

During handling of the above exception, another exception occurred:

Traceback (most recent call last):
  File "/usr/lib/python3.8/threading.py", line 890, in _bootstrap
    self._bootstrap_inner()
  File "/usr/lib/python3.8/threading.py", line 932, in _bootstrap_inner
    self.run()
  File "/usr/lib/python3.8/threading.py", line 870, in run
    self._target(*self._args, **self._kwargs)
  File "/usr/lib/python3.8/socketserver.py", line 650, in process_request_thread
    self.finish_request(request, client_address)
  File "/usr/lib/python3.8/socketserver.py", line 360, in finish_request
    self.RequestHandlerClass(request, client_address, self)
  File "/usr/lib/python3.8/socketserver.py", line 720, in __init__
    self.handle()
  File "/home/ubuntu/SuperShop/env/lib/python3.8/site-packages/django/core/servers/basehttp.py", line 172, in handle
    self.handle_one_request()
  File "/home/ubuntu/SuperShop/env/lib/python3.8/site-packages/django/core/servers/basehttp.py", line 197, in handle_one_request
    handler.run(self.server.get_app())
  File "/usr/lib/python3.8/wsgiref/handlers.py", line 137, in run
    self.result = application(self.environ, self.start_response)
  File "/home/ubuntu/SuperShop/env/lib/python3.8/site-packages/django/contrib/staticfiles/handlers.py", line 68, in __call__
    return self.application(environ, start_response)
  File "/home/ubuntu/SuperShop/env/lib/python3.8/site-packages/django/core/handlers/wsgi.py", line 133, in __call__
    response = self.get_response(request)
  File "/home/ubuntu/SuperShop/env/lib/python3.8/site-packages/django/core/handlers/base.py", line 75, in get_response
    response = self._middleware_chain(request)
  File "/home/ubuntu/SuperShop/env/lib/python3.8/site-packages/django/core/handlers/exception.py", line 34, in inner
    response = get_response(request)
  File "/home/ubuntu/SuperShop/env/lib/python3.8/site-packages/django/utils/deprecation.py", line 94, in __call__
    response = response or self.get_response(request)
  File "/home/ubuntu/SuperShop/env/lib/python3.8/site-packages/django/core/handlers/exception.py", line 34, in inner
    response = get_response(request)
  File "/home/ubuntu/SuperShop/env/lib/python3.8/site-packages/django/utils/deprecation.py", line 94, in __call__
    response = response or self.get_response(request)
  File "/home/ubuntu/SuperShop/env/lib/python3.8/site-packages/django/core/handlers/exception.py", line 34, in inner
    response = get_response(request)
  File "/home/ubuntu/SuperShop/env/lib/python3.8/site-packages/django/utils/deprecation.py", line 94, in __call__
    response = response or self.get_response(request)
  File "/home/ubuntu/SuperShop/env/lib/python3.8/site-packages/django/core/handlers/exception.py", line 34, in inner
    response = get_response(request)
  File "/home/ubuntu/SuperShop/env/lib/python3.8/site-packages/django/utils/deprecation.py", line 94, in __call__
    response = response or self.get_response(request)
  File "/home/ubuntu/SuperShop/env/lib/python3.8/site-packages/django/core/handlers/exception.py", line 34, in inner
    response = get_response(request)
  File "/home/ubuntu/SuperShop/env/lib/python3.8/site-packages/django/utils/deprecation.py", line 94, in __call__
    response = response or self.get_response(request)
  File "/home/ubuntu/SuperShop/env/lib/python3.8/site-packages/django/core/handlers/exception.py", line 34, in inner
    response = get_response(request)
  File "/home/ubuntu/SuperShop/env/lib/python3.8/site-packages/django/utils/deprecation.py", line 94, in __call__
    response = response or self.get_response(request)
  File "/home/ubuntu/SuperShop/env/lib/python3.8/site-packages/django/core/handlers/exception.py", line 34, in inner
    response = get_response(request)
  File "/home/ubuntu/SuperShop/env/lib/python3.8/site-packages/django/utils/deprecation.py", line 94, in __call__
    response = response or self.get_response(request)
  File "/home/ubuntu/SuperShop/env/lib/python3.8/site-packages/django/core/handlers/exception.py", line 34, in inner
    response = get_response(request)
  File "/home/ubuntu/SuperShop/env/lib/python3.8/site-packages/django/utils/deprecation.py", line 94, in __call__
    response = response or self.get_response(request)
  File "/home/ubuntu/SuperShop/env/lib/python3.8/site-packages/django/core/handlers/exception.py", line 34, in inner
    response = get_response(request)
  File "/home/ubuntu/SuperShop/env/lib/python3.8/site-packages/django/core/handlers/base.py", line 113, in _get_response
    response = wrapped_callback(request, *callback_args, **callback_kwargs)
> File "/home/ubuntu/SuperShop/cart/views.py", line 50, in cart_detail
    recommended_products = r.suggest_products_for(cart_products,
  File "/home/ubuntu/SuperShop/shop/recommender.py", line 41, in suggest_products_for
    suggestions = r.zrange(
  File "/home/ubuntu/SuperShop/env/lib/python3.8/site-packages/redis/client.py", line 2757, in zrange
    return self.zrevrange(name, start, end, withscores,
  File "/home/ubuntu/SuperShop/env/lib/python3.8/site-packages/redis/client.py", line 2884, in zrevrange
    return self.execute_command(*pieces, **options)
  File "/home/ubuntu/SuperShop/env/lib/python3.8/site-packages/redis/client.py", line 875, in execute_command
    conn = self.connection or pool.get_connection(command_name, **options)
  File "/home/ubuntu/SuperShop/env/lib/python3.8/site-packages/redis/connection.py", line 1185, in get_connection
    connection.connect()
  File "/home/ubuntu/SuperShop/env/lib/python3.8/site-packages/redis/connection.py", line 557, in connect
    raise ConnectionError(self._error_message(e))
redis.exceptions.ConnectionError: Error 111 connecting to localhost:6379. Connection refused.
2021-03-29 08:38:17.944 | ERROR    | cart.views:cart_detail:50 - An error has been caught in function 'cart_detail', process 'MainProcess' (2185), thread 'Thread-30' (139747450226432):
Traceback (most recent call last):
  File "/home/ubuntu/SuperShop/env/lib/python3.8/site-packages/redis/connection.py", line 552, in connect
    sock = self._connect()
  File "/home/ubuntu/SuperShop/env/lib/python3.8/site-packages/redis/connection.py", line 609, in _connect
    raise err
  File "/home/ubuntu/SuperShop/env/lib/python3.8/site-packages/redis/connection.py", line 597, in _connect
    sock.connect(socket_address)
ConnectionRefusedError: [Errno 111] Connection refused

During handling of the above exception, another exception occurred:

Traceback (most recent call last):
  File "/usr/lib/python3.8/threading.py", line 890, in _bootstrap
    self._bootstrap_inner()
  File "/usr/lib/python3.8/threading.py", line 932, in _bootstrap_inner
    self.run()
  File "/usr/lib/python3.8/threading.py", line 870, in run
    self._target(*self._args, **self._kwargs)
  File "/usr/lib/python3.8/socketserver.py", line 650, in process_request_thread
    self.finish_request(request, client_address)
  File "/usr/lib/python3.8/socketserver.py", line 360, in finish_request
    self.RequestHandlerClass(request, client_address, self)
  File "/usr/lib/python3.8/socketserver.py", line 720, in __init__
    self.handle()
  File "/home/ubuntu/SuperShop/env/lib/python3.8/site-packages/django/core/servers/basehttp.py", line 172, in handle
    self.handle_one_request()
  File "/home/ubuntu/SuperShop/env/lib/python3.8/site-packages/django/core/servers/basehttp.py", line 197, in handle_one_request
    handler.run(self.server.get_app())
  File "/usr/lib/python3.8/wsgiref/handlers.py", line 137, in run
    self.result = application(self.environ, self.start_response)
  File "/home/ubuntu/SuperShop/env/lib/python3.8/site-packages/django/contrib/staticfiles/handlers.py", line 68, in __call__
    return self.application(environ, start_response)
  File "/home/ubuntu/SuperShop/env/lib/python3.8/site-packages/django/core/handlers/wsgi.py", line 133, in __call__
    response = self.get_response(request)
  File "/home/ubuntu/SuperShop/env/lib/python3.8/site-packages/django/core/handlers/base.py", line 75, in get_response
    response = self._middleware_chain(request)
  File "/home/ubuntu/SuperShop/env/lib/python3.8/site-packages/django/core/handlers/exception.py", line 34, in inner
    response = get_response(request)
  File "/home/ubuntu/SuperShop/env/lib/python3.8/site-packages/django/utils/deprecation.py", line 94, in __call__
    response = response or self.get_response(request)
  File "/home/ubuntu/SuperShop/env/lib/python3.8/site-packages/django/core/handlers/exception.py", line 34, in inner
    response = get_response(request)
  File "/home/ubuntu/SuperShop/env/lib/python3.8/site-packages/django/utils/deprecation.py", line 94, in __call__
    response = response or self.get_response(request)
  File "/home/ubuntu/SuperShop/env/lib/python3.8/site-packages/django/core/handlers/exception.py", line 34, in inner
    response = get_response(request)
  File "/home/ubuntu/SuperShop/env/lib/python3.8/site-packages/django/utils/deprecation.py", line 94, in __call__
    response = response or self.get_response(request)
  File "/home/ubuntu/SuperShop/env/lib/python3.8/site-packages/django/core/handlers/exception.py", line 34, in inner
    response = get_response(request)
  File "/home/ubuntu/SuperShop/env/lib/python3.8/site-packages/django/utils/deprecation.py", line 94, in __call__
    response = response or self.get_response(request)
  File "/home/ubuntu/SuperShop/env/lib/python3.8/site-packages/django/core/handlers/exception.py", line 34, in inner
    response = get_response(request)
  File "/home/ubuntu/SuperShop/env/lib/python3.8/site-packages/django/utils/deprecation.py", line 94, in __call__
    response = response or self.get_response(request)
  File "/home/ubuntu/SuperShop/env/lib/python3.8/site-packages/django/core/handlers/exception.py", line 34, in inner
    response = get_response(request)
  File "/home/ubuntu/SuperShop/env/lib/python3.8/site-packages/django/utils/deprecation.py", line 94, in __call__
    response = response or self.get_response(request)
  File "/home/ubuntu/SuperShop/env/lib/python3.8/site-packages/django/core/handlers/exception.py", line 34, in inner
    response = get_response(request)
  File "/home/ubuntu/SuperShop/env/lib/python3.8/site-packages/django/utils/deprecation.py", line 94, in __call__
    response = response or self.get_response(request)
  File "/home/ubuntu/SuperShop/env/lib/python3.8/site-packages/django/core/handlers/exception.py", line 34, in inner
    response = get_response(request)
  File "/home/ubuntu/SuperShop/env/lib/python3.8/site-packages/django/utils/deprecation.py", line 94, in __call__
    response = response or self.get_response(request)
  File "/home/ubuntu/SuperShop/env/lib/python3.8/site-packages/django/core/handlers/exception.py", line 34, in inner
    response = get_response(request)
  File "/home/ubuntu/SuperShop/env/lib/python3.8/site-packages/django/core/handlers/base.py", line 113, in _get_response
    response = wrapped_callback(request, *callback_args, **callback_kwargs)
> File "/home/ubuntu/SuperShop/cart/views.py", line 50, in cart_detail
    recommended_products = r.suggest_products_for(cart_products,
  File "/home/ubuntu/SuperShop/shop/recommender.py", line 41, in suggest_products_for
    suggestions = r.zrange(
  File "/home/ubuntu/SuperShop/env/lib/python3.8/site-packages/redis/client.py", line 2757, in zrange
    return self.zrevrange(name, start, end, withscores,
  File "/home/ubuntu/SuperShop/env/lib/python3.8/site-packages/redis/client.py", line 2884, in zrevrange
    return self.execute_command(*pieces, **options)
  File "/home/ubuntu/SuperShop/env/lib/python3.8/site-packages/redis/client.py", line 875, in execute_command
    conn = self.connection or pool.get_connection(command_name, **options)
  File "/home/ubuntu/SuperShop/env/lib/python3.8/site-packages/redis/connection.py", line 1185, in get_connection
    connection.connect()
  File "/home/ubuntu/SuperShop/env/lib/python3.8/site-packages/redis/connection.py", line 557, in connect
    raise ConnectionError(self._error_message(e))
redis.exceptions.ConnectionError: Error 111 connecting to localhost:6379. Connection refused.
2021-03-29 17:31:16.276 | ERROR    | cart.views:cart_detail:50 - An error has been caught in function 'cart_detail', process 'MainProcess' (1234), thread 'Thread-4' (140070223607552):
Traceback (most recent call last):
  File "/home/ubuntu/SuperShop/env/lib/python3.8/site-packages/redis/connection.py", line 552, in connect
    sock = self._connect()
  File "/home/ubuntu/SuperShop/env/lib/python3.8/site-packages/redis/connection.py", line 609, in _connect
    raise err
  File "/home/ubuntu/SuperShop/env/lib/python3.8/site-packages/redis/connection.py", line 597, in _connect
    sock.connect(socket_address)
ConnectionRefusedError: [Errno 111] Connection refused

During handling of the above exception, another exception occurred:

Traceback (most recent call last):
  File "/usr/lib/python3.8/threading.py", line 890, in _bootstrap
    self._bootstrap_inner()
  File "/usr/lib/python3.8/threading.py", line 932, in _bootstrap_inner
    self.run()
  File "/usr/lib/python3.8/threading.py", line 870, in run
    self._target(*self._args, **self._kwargs)
  File "/usr/lib/python3.8/socketserver.py", line 650, in process_request_thread
    self.finish_request(request, client_address)
  File "/usr/lib/python3.8/socketserver.py", line 360, in finish_request
    self.RequestHandlerClass(request, client_address, self)
  File "/usr/lib/python3.8/socketserver.py", line 720, in __init__
    self.handle()
  File "/home/ubuntu/SuperShop/env/lib/python3.8/site-packages/django/core/servers/basehttp.py", line 174, in handle
    self.handle_one_request()
  File "/home/ubuntu/SuperShop/env/lib/python3.8/site-packages/django/core/servers/basehttp.py", line 197, in handle_one_request
    handler.run(self.server.get_app())
  File "/usr/lib/python3.8/wsgiref/handlers.py", line 137, in run
    self.result = application(self.environ, self.start_response)
  File "/home/ubuntu/SuperShop/env/lib/python3.8/site-packages/django/contrib/staticfiles/handlers.py", line 68, in __call__
    return self.application(environ, start_response)
  File "/home/ubuntu/SuperShop/env/lib/python3.8/site-packages/django/core/handlers/wsgi.py", line 133, in __call__
    response = self.get_response(request)
  File "/home/ubuntu/SuperShop/env/lib/python3.8/site-packages/django/core/handlers/base.py", line 75, in get_response
    response = self._middleware_chain(request)
  File "/home/ubuntu/SuperShop/env/lib/python3.8/site-packages/django/core/handlers/exception.py", line 34, in inner
    response = get_response(request)
  File "/home/ubuntu/SuperShop/env/lib/python3.8/site-packages/django/utils/deprecation.py", line 94, in __call__
    response = response or self.get_response(request)
  File "/home/ubuntu/SuperShop/env/lib/python3.8/site-packages/django/core/handlers/exception.py", line 34, in inner
    response = get_response(request)
  File "/home/ubuntu/SuperShop/env/lib/python3.8/site-packages/django/utils/deprecation.py", line 94, in __call__
    response = response or self.get_response(request)
  File "/home/ubuntu/SuperShop/env/lib/python3.8/site-packages/django/core/handlers/exception.py", line 34, in inner
    response = get_response(request)
  File "/home/ubuntu/SuperShop/env/lib/python3.8/site-packages/django/utils/deprecation.py", line 94, in __call__
    response = response or self.get_response(request)
  File "/home/ubuntu/SuperShop/env/lib/python3.8/site-packages/django/core/handlers/exception.py", line 34, in inner
    response = get_response(request)
  File "/home/ubuntu/SuperShop/env/lib/python3.8/site-packages/django/utils/deprecation.py", line 94, in __call__
    response = response or self.get_response(request)
  File "/home/ubuntu/SuperShop/env/lib/python3.8/site-packages/django/core/handlers/exception.py", line 34, in inner
    response = get_response(request)
  File "/home/ubuntu/SuperShop/env/lib/python3.8/site-packages/django/utils/deprecation.py", line 94, in __call__
    response = response or self.get_response(request)
  File "/home/ubuntu/SuperShop/env/lib/python3.8/site-packages/django/core/handlers/exception.py", line 34, in inner
    response = get_response(request)
  File "/home/ubuntu/SuperShop/env/lib/python3.8/site-packages/django/utils/deprecation.py", line 94, in __call__
    response = response or self.get_response(request)
  File "/home/ubuntu/SuperShop/env/lib/python3.8/site-packages/django/core/handlers/exception.py", line 34, in inner
    response = get_response(request)
  File "/home/ubuntu/SuperShop/env/lib/python3.8/site-packages/django/utils/deprecation.py", line 94, in __call__
    response = response or self.get_response(request)
  File "/home/ubuntu/SuperShop/env/lib/python3.8/site-packages/django/core/handlers/exception.py", line 34, in inner
    response = get_response(request)
  File "/home/ubuntu/SuperShop/env/lib/python3.8/site-packages/django/utils/deprecation.py", line 94, in __call__
    response = response or self.get_response(request)
  File "/home/ubuntu/SuperShop/env/lib/python3.8/site-packages/django/core/handlers/exception.py", line 34, in inner
    response = get_response(request)
  File "/home/ubuntu/SuperShop/env/lib/python3.8/site-packages/django/core/handlers/base.py", line 113, in _get_response
    response = wrapped_callback(request, *callback_args, **callback_kwargs)
> File "/home/ubuntu/SuperShop/cart/views.py", line 50, in cart_detail
    recommended_products = r.suggest_products_for(cart_products,
  File "/home/ubuntu/SuperShop/shop/recommender.py", line 41, in suggest_products_for
    suggestions = r.zrange(
  File "/home/ubuntu/SuperShop/env/lib/python3.8/site-packages/redis/client.py", line 2757, in zrange
    return self.zrevrange(name, start, end, withscores,
  File "/home/ubuntu/SuperShop/env/lib/python3.8/site-packages/redis/client.py", line 2884, in zrevrange
    return self.execute_command(*pieces, **options)
  File "/home/ubuntu/SuperShop/env/lib/python3.8/site-packages/redis/client.py", line 875, in execute_command
    conn = self.connection or pool.get_connection(command_name, **options)
  File "/home/ubuntu/SuperShop/env/lib/python3.8/site-packages/redis/connection.py", line 1185, in get_connection
    connection.connect()
  File "/home/ubuntu/SuperShop/env/lib/python3.8/site-packages/redis/connection.py", line 557, in connect
    raise ConnectionError(self._error_message(e))
redis.exceptions.ConnectionError: Error 111 connecting to localhost:6379. Connection refused.
2021-03-29 17:32:09.461 | ERROR    | cart.views:cart_detail:50 - An error has been caught in function 'cart_detail', process 'MainProcess' (1234), thread 'Thread-4' (140070223607552):
Traceback (most recent call last):
  File "/home/ubuntu/SuperShop/env/lib/python3.8/site-packages/redis/connection.py", line 552, in connect
    sock = self._connect()
  File "/home/ubuntu/SuperShop/env/lib/python3.8/site-packages/redis/connection.py", line 609, in _connect
    raise err
  File "/home/ubuntu/SuperShop/env/lib/python3.8/site-packages/redis/connection.py", line 597, in _connect
    sock.connect(socket_address)
ConnectionRefusedError: [Errno 111] Connection refused

During handling of the above exception, another exception occurred:

Traceback (most recent call last):
  File "/usr/lib/python3.8/threading.py", line 890, in _bootstrap
    self._bootstrap_inner()
  File "/usr/lib/python3.8/threading.py", line 932, in _bootstrap_inner
    self.run()
  File "/usr/lib/python3.8/threading.py", line 870, in run
    self._target(*self._args, **self._kwargs)
  File "/usr/lib/python3.8/socketserver.py", line 650, in process_request_thread
    self.finish_request(request, client_address)
  File "/usr/lib/python3.8/socketserver.py", line 360, in finish_request
    self.RequestHandlerClass(request, client_address, self)
  File "/usr/lib/python3.8/socketserver.py", line 720, in __init__
    self.handle()
  File "/home/ubuntu/SuperShop/env/lib/python3.8/site-packages/django/core/servers/basehttp.py", line 174, in handle
    self.handle_one_request()
  File "/home/ubuntu/SuperShop/env/lib/python3.8/site-packages/django/core/servers/basehttp.py", line 197, in handle_one_request
    handler.run(self.server.get_app())
  File "/usr/lib/python3.8/wsgiref/handlers.py", line 137, in run
    self.result = application(self.environ, self.start_response)
  File "/home/ubuntu/SuperShop/env/lib/python3.8/site-packages/django/contrib/staticfiles/handlers.py", line 68, in __call__
    return self.application(environ, start_response)
  File "/home/ubuntu/SuperShop/env/lib/python3.8/site-packages/django/core/handlers/wsgi.py", line 133, in __call__
    response = self.get_response(request)
  File "/home/ubuntu/SuperShop/env/lib/python3.8/site-packages/django/core/handlers/base.py", line 75, in get_response
    response = self._middleware_chain(request)
  File "/home/ubuntu/SuperShop/env/lib/python3.8/site-packages/django/core/handlers/exception.py", line 34, in inner
    response = get_response(request)
  File "/home/ubuntu/SuperShop/env/lib/python3.8/site-packages/django/utils/deprecation.py", line 94, in __call__
    response = response or self.get_response(request)
  File "/home/ubuntu/SuperShop/env/lib/python3.8/site-packages/django/core/handlers/exception.py", line 34, in inner
    response = get_response(request)
  File "/home/ubuntu/SuperShop/env/lib/python3.8/site-packages/django/utils/deprecation.py", line 94, in __call__
    response = response or self.get_response(request)
  File "/home/ubuntu/SuperShop/env/lib/python3.8/site-packages/django/core/handlers/exception.py", line 34, in inner
    response = get_response(request)
  File "/home/ubuntu/SuperShop/env/lib/python3.8/site-packages/django/utils/deprecation.py", line 94, in __call__
    response = response or self.get_response(request)
  File "/home/ubuntu/SuperShop/env/lib/python3.8/site-packages/django/core/handlers/exception.py", line 34, in inner
    response = get_response(request)
  File "/home/ubuntu/SuperShop/env/lib/python3.8/site-packages/django/utils/deprecation.py", line 94, in __call__
    response = response or self.get_response(request)
  File "/home/ubuntu/SuperShop/env/lib/python3.8/site-packages/django/core/handlers/exception.py", line 34, in inner
    response = get_response(request)
  File "/home/ubuntu/SuperShop/env/lib/python3.8/site-packages/django/utils/deprecation.py", line 94, in __call__
    response = response or self.get_response(request)
  File "/home/ubuntu/SuperShop/env/lib/python3.8/site-packages/django/core/handlers/exception.py", line 34, in inner
    response = get_response(request)
  File "/home/ubuntu/SuperShop/env/lib/python3.8/site-packages/django/utils/deprecation.py", line 94, in __call__
    response = response or self.get_response(request)
  File "/home/ubuntu/SuperShop/env/lib/python3.8/site-packages/django/core/handlers/exception.py", line 34, in inner
    response = get_response(request)
  File "/home/ubuntu/SuperShop/env/lib/python3.8/site-packages/django/utils/deprecation.py", line 94, in __call__
    response = response or self.get_response(request)
  File "/home/ubuntu/SuperShop/env/lib/python3.8/site-packages/django/core/handlers/exception.py", line 34, in inner
    response = get_response(request)
  File "/home/ubuntu/SuperShop/env/lib/python3.8/site-packages/django/utils/deprecation.py", line 94, in __call__
    response = response or self.get_response(request)
  File "/home/ubuntu/SuperShop/env/lib/python3.8/site-packages/django/core/handlers/exception.py", line 34, in inner
    response = get_response(request)
  File "/home/ubuntu/SuperShop/env/lib/python3.8/site-packages/django/core/handlers/base.py", line 113, in _get_response
    response = wrapped_callback(request, *callback_args, **callback_kwargs)
> File "/home/ubuntu/SuperShop/cart/views.py", line 50, in cart_detail
    recommended_products = r.suggest_products_for(cart_products,
  File "/home/ubuntu/SuperShop/shop/recommender.py", line 51, in suggest_products_for
    r.zunionstore(tmp_key, keys)
  File "/home/ubuntu/SuperShop/env/lib/python3.8/site-packages/redis/client.py", line 2931, in zunionstore
    return self._zaggregate('ZUNIONSTORE', dest, keys, aggregate)
  File "/home/ubuntu/SuperShop/env/lib/python3.8/site-packages/redis/client.py", line 2946, in _zaggregate
    return self.execute_command(*pieces)
  File "/home/ubuntu/SuperShop/env/lib/python3.8/site-packages/redis/client.py", line 875, in execute_command
    conn = self.connection or pool.get_connection(command_name, **options)
  File "/home/ubuntu/SuperShop/env/lib/python3.8/site-packages/redis/connection.py", line 1185, in get_connection
    connection.connect()
  File "/home/ubuntu/SuperShop/env/lib/python3.8/site-packages/redis/connection.py", line 557, in connect
    raise ConnectionError(self._error_message(e))
redis.exceptions.ConnectionError: Error 111 connecting to localhost:6379. Connection refused.
2021-03-29 17:42:12.379 | ERROR    | cart.views:cart_detail:50 - An error has been caught in function 'cart_detail', process 'MainProcess' (2133), thread 'Thread-1' (140369830975232):
Traceback (most recent call last):
  File "/home/ubuntu/SuperShop/env/lib/python3.8/site-packages/redis/connection.py", line 552, in connect
    sock = self._connect()
  File "/home/ubuntu/SuperShop/env/lib/python3.8/site-packages/redis/connection.py", line 609, in _connect
    raise err
  File "/home/ubuntu/SuperShop/env/lib/python3.8/site-packages/redis/connection.py", line 597, in _connect
    sock.connect(socket_address)
ConnectionRefusedError: [Errno 111] Connection refused

During handling of the above exception, another exception occurred:

Traceback (most recent call last):
  File "/usr/lib/python3.8/threading.py", line 890, in _bootstrap
    self._bootstrap_inner()
  File "/usr/lib/python3.8/threading.py", line 932, in _bootstrap_inner
    self.run()
  File "/usr/lib/python3.8/threading.py", line 870, in run
    self._target(*self._args, **self._kwargs)
  File "/usr/lib/python3.8/socketserver.py", line 650, in process_request_thread
    self.finish_request(request, client_address)
  File "/usr/lib/python3.8/socketserver.py", line 360, in finish_request
    self.RequestHandlerClass(request, client_address, self)
  File "/usr/lib/python3.8/socketserver.py", line 720, in __init__
    self.handle()
  File "/home/ubuntu/SuperShop/env/lib/python3.8/site-packages/django/core/servers/basehttp.py", line 172, in handle
    self.handle_one_request()
  File "/home/ubuntu/SuperShop/env/lib/python3.8/site-packages/django/core/servers/basehttp.py", line 197, in handle_one_request
    handler.run(self.server.get_app())
  File "/usr/lib/python3.8/wsgiref/handlers.py", line 137, in run
    self.result = application(self.environ, self.start_response)
  File "/home/ubuntu/SuperShop/env/lib/python3.8/site-packages/django/contrib/staticfiles/handlers.py", line 68, in __call__
    return self.application(environ, start_response)
  File "/home/ubuntu/SuperShop/env/lib/python3.8/site-packages/django/core/handlers/wsgi.py", line 133, in __call__
    response = self.get_response(request)
  File "/home/ubuntu/SuperShop/env/lib/python3.8/site-packages/django/core/handlers/base.py", line 75, in get_response
    response = self._middleware_chain(request)
  File "/home/ubuntu/SuperShop/env/lib/python3.8/site-packages/django/core/handlers/exception.py", line 34, in inner
    response = get_response(request)
  File "/home/ubuntu/SuperShop/env/lib/python3.8/site-packages/django/utils/deprecation.py", line 94, in __call__
    response = response or self.get_response(request)
  File "/home/ubuntu/SuperShop/env/lib/python3.8/site-packages/django/core/handlers/exception.py", line 34, in inner
    response = get_response(request)
  File "/home/ubuntu/SuperShop/env/lib/python3.8/site-packages/django/utils/deprecation.py", line 94, in __call__
    response = response or self.get_response(request)
  File "/home/ubuntu/SuperShop/env/lib/python3.8/site-packages/django/core/handlers/exception.py", line 34, in inner
    response = get_response(request)
  File "/home/ubuntu/SuperShop/env/lib/python3.8/site-packages/django/utils/deprecation.py", line 94, in __call__
    response = response or self.get_response(request)
  File "/home/ubuntu/SuperShop/env/lib/python3.8/site-packages/django/core/handlers/exception.py", line 34, in inner
    response = get_response(request)
  File "/home/ubuntu/SuperShop/env/lib/python3.8/site-packages/django/utils/deprecation.py", line 94, in __call__
    response = response or self.get_response(request)
  File "/home/ubuntu/SuperShop/env/lib/python3.8/site-packages/django/core/handlers/exception.py", line 34, in inner
    response = get_response(request)
  File "/home/ubuntu/SuperShop/env/lib/python3.8/site-packages/django/utils/deprecation.py", line 94, in __call__
    response = response or self.get_response(request)
  File "/home/ubuntu/SuperShop/env/lib/python3.8/site-packages/django/core/handlers/exception.py", line 34, in inner
    response = get_response(request)
  File "/home/ubuntu/SuperShop/env/lib/python3.8/site-packages/django/utils/deprecation.py", line 94, in __call__
    response = response or self.get_response(request)
  File "/home/ubuntu/SuperShop/env/lib/python3.8/site-packages/django/core/handlers/exception.py", line 34, in inner
    response = get_response(request)
  File "/home/ubuntu/SuperShop/env/lib/python3.8/site-packages/django/utils/deprecation.py", line 94, in __call__
    response = response or self.get_response(request)
  File "/home/ubuntu/SuperShop/env/lib/python3.8/site-packages/django/core/handlers/exception.py", line 34, in inner
    response = get_response(request)
  File "/home/ubuntu/SuperShop/env/lib/python3.8/site-packages/django/utils/deprecation.py", line 94, in __call__
    response = response or self.get_response(request)
  File "/home/ubuntu/SuperShop/env/lib/python3.8/site-packages/django/core/handlers/exception.py", line 34, in inner
    response = get_response(request)
  File "/home/ubuntu/SuperShop/env/lib/python3.8/site-packages/django/core/handlers/base.py", line 113, in _get_response
    response = wrapped_callback(request, *callback_args, **callback_kwargs)
> File "/home/ubuntu/SuperShop/cart/views.py", line 50, in cart_detail
    recommended_products = r.suggest_products_for(cart_products,
  File "/home/ubuntu/SuperShop/shop/recommender.py", line 51, in suggest_products_for
    r.zunionstore(tmp_key, keys)
  File "/home/ubuntu/SuperShop/env/lib/python3.8/site-packages/redis/client.py", line 2931, in zunionstore
    return self._zaggregate('ZUNIONSTORE', dest, keys, aggregate)
  File "/home/ubuntu/SuperShop/env/lib/python3.8/site-packages/redis/client.py", line 2946, in _zaggregate
    return self.execute_command(*pieces)
  File "/home/ubuntu/SuperShop/env/lib/python3.8/site-packages/redis/client.py", line 875, in execute_command
    conn = self.connection or pool.get_connection(command_name, **options)
  File "/home/ubuntu/SuperShop/env/lib/python3.8/site-packages/redis/connection.py", line 1185, in get_connection
    connection.connect()
  File "/home/ubuntu/SuperShop/env/lib/python3.8/site-packages/redis/connection.py", line 557, in connect
    raise ConnectionError(self._error_message(e))
redis.exceptions.ConnectionError: Error 111 connecting to localhost:6379. Connection refused.
2021-03-29 17:42:43.106 | ERROR    | cart.views:cart_detail:50 - An error has been caught in function 'cart_detail', process 'MainProcess' (2133), thread 'Thread-3' (140369820485376):
Traceback (most recent call last):
  File "/home/ubuntu/SuperShop/env/lib/python3.8/site-packages/redis/connection.py", line 552, in connect
    sock = self._connect()
  File "/home/ubuntu/SuperShop/env/lib/python3.8/site-packages/redis/connection.py", line 609, in _connect
    raise err
  File "/home/ubuntu/SuperShop/env/lib/python3.8/site-packages/redis/connection.py", line 597, in _connect
    sock.connect(socket_address)
ConnectionRefusedError: [Errno 111] Connection refused

During handling of the above exception, another exception occurred:

Traceback (most recent call last):
  File "/usr/lib/python3.8/threading.py", line 890, in _bootstrap
    self._bootstrap_inner()
  File "/usr/lib/python3.8/threading.py", line 932, in _bootstrap_inner
    self.run()
  File "/usr/lib/python3.8/threading.py", line 870, in run
    self._target(*self._args, **self._kwargs)
  File "/usr/lib/python3.8/socketserver.py", line 650, in process_request_thread
    self.finish_request(request, client_address)
  File "/usr/lib/python3.8/socketserver.py", line 360, in finish_request
    self.RequestHandlerClass(request, client_address, self)
  File "/usr/lib/python3.8/socketserver.py", line 720, in __init__
    self.handle()
  File "/home/ubuntu/SuperShop/env/lib/python3.8/site-packages/django/core/servers/basehttp.py", line 172, in handle
    self.handle_one_request()
  File "/home/ubuntu/SuperShop/env/lib/python3.8/site-packages/django/core/servers/basehttp.py", line 197, in handle_one_request
    handler.run(self.server.get_app())
  File "/usr/lib/python3.8/wsgiref/handlers.py", line 137, in run
    self.result = application(self.environ, self.start_response)
  File "/home/ubuntu/SuperShop/env/lib/python3.8/site-packages/django/contrib/staticfiles/handlers.py", line 68, in __call__
    return self.application(environ, start_response)
  File "/home/ubuntu/SuperShop/env/lib/python3.8/site-packages/django/core/handlers/wsgi.py", line 133, in __call__
    response = self.get_response(request)
  File "/home/ubuntu/SuperShop/env/lib/python3.8/site-packages/django/core/handlers/base.py", line 75, in get_response
    response = self._middleware_chain(request)
  File "/home/ubuntu/SuperShop/env/lib/python3.8/site-packages/django/core/handlers/exception.py", line 34, in inner
    response = get_response(request)
  File "/home/ubuntu/SuperShop/env/lib/python3.8/site-packages/django/utils/deprecation.py", line 94, in __call__
    response = response or self.get_response(request)
  File "/home/ubuntu/SuperShop/env/lib/python3.8/site-packages/django/core/handlers/exception.py", line 34, in inner
    response = get_response(request)
  File "/home/ubuntu/SuperShop/env/lib/python3.8/site-packages/django/utils/deprecation.py", line 94, in __call__
    response = response or self.get_response(request)
  File "/home/ubuntu/SuperShop/env/lib/python3.8/site-packages/django/core/handlers/exception.py", line 34, in inner
    response = get_response(request)
  File "/home/ubuntu/SuperShop/env/lib/python3.8/site-packages/django/utils/deprecation.py", line 94, in __call__
    response = response or self.get_response(request)
  File "/home/ubuntu/SuperShop/env/lib/python3.8/site-packages/django/core/handlers/exception.py", line 34, in inner
    response = get_response(request)
  File "/home/ubuntu/SuperShop/env/lib/python3.8/site-packages/django/utils/deprecation.py", line 94, in __call__
    response = response or self.get_response(request)
  File "/home/ubuntu/SuperShop/env/lib/python3.8/site-packages/django/core/handlers/exception.py", line 34, in inner
    response = get_response(request)
  File "/home/ubuntu/SuperShop/env/lib/python3.8/site-packages/django/utils/deprecation.py", line 94, in __call__
    response = response or self.get_response(request)
  File "/home/ubuntu/SuperShop/env/lib/python3.8/site-packages/django/core/handlers/exception.py", line 34, in inner
    response = get_response(request)
  File "/home/ubuntu/SuperShop/env/lib/python3.8/site-packages/django/utils/deprecation.py", line 94, in __call__
    response = response or self.get_response(request)
  File "/home/ubuntu/SuperShop/env/lib/python3.8/site-packages/django/core/handlers/exception.py", line 34, in inner
    response = get_response(request)
  File "/home/ubuntu/SuperShop/env/lib/python3.8/site-packages/django/utils/deprecation.py", line 94, in __call__
    response = response or self.get_response(request)
  File "/home/ubuntu/SuperShop/env/lib/python3.8/site-packages/django/core/handlers/exception.py", line 34, in inner
    response = get_response(request)
  File "/home/ubuntu/SuperShop/env/lib/python3.8/site-packages/django/utils/deprecation.py", line 94, in __call__
    response = response or self.get_response(request)
  File "/home/ubuntu/SuperShop/env/lib/python3.8/site-packages/django/core/handlers/exception.py", line 34, in inner
    response = get_response(request)
  File "/home/ubuntu/SuperShop/env/lib/python3.8/site-packages/django/core/handlers/base.py", line 113, in _get_response
    response = wrapped_callback(request, *callback_args, **callback_kwargs)
> File "/home/ubuntu/SuperShop/cart/views.py", line 50, in cart_detail
    recommended_products = r.suggest_products_for(cart_products,
  File "/home/ubuntu/SuperShop/shop/recommender.py", line 51, in suggest_products_for
    r.zunionstore(tmp_key, keys)
  File "/home/ubuntu/SuperShop/env/lib/python3.8/site-packages/redis/client.py", line 2931, in zunionstore
    return self._zaggregate('ZUNIONSTORE', dest, keys, aggregate)
  File "/home/ubuntu/SuperShop/env/lib/python3.8/site-packages/redis/client.py", line 2946, in _zaggregate
    return self.execute_command(*pieces)
  File "/home/ubuntu/SuperShop/env/lib/python3.8/site-packages/redis/client.py", line 875, in execute_command
    conn = self.connection or pool.get_connection(command_name, **options)
  File "/home/ubuntu/SuperShop/env/lib/python3.8/site-packages/redis/connection.py", line 1185, in get_connection
    connection.connect()
  File "/home/ubuntu/SuperShop/env/lib/python3.8/site-packages/redis/connection.py", line 557, in connect
    raise ConnectionError(self._error_message(e))
redis.exceptions.ConnectionError: Error 111 connecting to localhost:6379. Connection refused.
2021-03-29 18:39:10.736 | ERROR    | django.core.handlers.base:_get_response:113 - An error has been caught in function '_get_response', process 'MainProcess' (28381), thread 'Thread-1' (140049146935040):
Traceback (most recent call last):
  File "/home/ubuntu/SuperShop/env/lib/python3.8/site-packages/django/shortcuts.py", line 76, in get_object_or_404
    return queryset.get(*args, **kwargs)
  File "/home/ubuntu/SuperShop/env/lib/python3.8/site-packages/django/db/models/query.py", line 415, in get
    raise self.model.DoesNotExist(
shop.models.Category.DoesNotExist: Category matching query does not exist.

During handling of the above exception, another exception occurred:

Traceback (most recent call last):
  File "/usr/lib/python3.8/threading.py", line 890, in _bootstrap
    self._bootstrap_inner()
  File "/usr/lib/python3.8/threading.py", line 932, in _bootstrap_inner
    self.run()
  File "/usr/lib/python3.8/threading.py", line 870, in run
    self._target(*self._args, **self._kwargs)
  File "/usr/lib/python3.8/socketserver.py", line 650, in process_request_thread
    self.finish_request(request, client_address)
  File "/usr/lib/python3.8/socketserver.py", line 360, in finish_request
    self.RequestHandlerClass(request, client_address, self)
  File "/usr/lib/python3.8/socketserver.py", line 720, in __init__
    self.handle()
  File "/home/ubuntu/SuperShop/env/lib/python3.8/site-packages/django/core/servers/basehttp.py", line 172, in handle
    self.handle_one_request()
  File "/home/ubuntu/SuperShop/env/lib/python3.8/site-packages/django/core/servers/basehttp.py", line 197, in handle_one_request
    handler.run(self.server.get_app())
  File "/usr/lib/python3.8/wsgiref/handlers.py", line 137, in run
    self.result = application(self.environ, self.start_response)
  File "/home/ubuntu/SuperShop/env/lib/python3.8/site-packages/django/contrib/staticfiles/handlers.py", line 68, in __call__
    return self.application(environ, start_response)
  File "/home/ubuntu/SuperShop/env/lib/python3.8/site-packages/django/core/handlers/wsgi.py", line 133, in __call__
    response = self.get_response(request)
  File "/home/ubuntu/SuperShop/env/lib/python3.8/site-packages/django/core/handlers/base.py", line 75, in get_response
    response = self._middleware_chain(request)
  File "/home/ubuntu/SuperShop/env/lib/python3.8/site-packages/django/core/handlers/exception.py", line 34, in inner
    response = get_response(request)
  File "/home/ubuntu/SuperShop/env/lib/python3.8/site-packages/django/utils/deprecation.py", line 94, in __call__
    response = response or self.get_response(request)
  File "/home/ubuntu/SuperShop/env/lib/python3.8/site-packages/django/core/handlers/exception.py", line 34, in inner
    response = get_response(request)
  File "/home/ubuntu/SuperShop/env/lib/python3.8/site-packages/django/utils/deprecation.py", line 94, in __call__
    response = response or self.get_response(request)
  File "/home/ubuntu/SuperShop/env/lib/python3.8/site-packages/django/core/handlers/exception.py", line 34, in inner
    response = get_response(request)
  File "/home/ubuntu/SuperShop/env/lib/python3.8/site-packages/django/utils/deprecation.py", line 94, in __call__
    response = response or self.get_response(request)
  File "/home/ubuntu/SuperShop/env/lib/python3.8/site-packages/django/core/handlers/exception.py", line 34, in inner
    response = get_response(request)
  File "/home/ubuntu/SuperShop/env/lib/python3.8/site-packages/django/utils/deprecation.py", line 94, in __call__
    response = response or self.get_response(request)
  File "/home/ubuntu/SuperShop/env/lib/python3.8/site-packages/django/core/handlers/exception.py", line 34, in inner
    response = get_response(request)
  File "/home/ubuntu/SuperShop/env/lib/python3.8/site-packages/django/utils/deprecation.py", line 94, in __call__
    response = response or self.get_response(request)
  File "/home/ubuntu/SuperShop/env/lib/python3.8/site-packages/django/core/handlers/exception.py", line 34, in inner
    response = get_response(request)
  File "/home/ubuntu/SuperShop/env/lib/python3.8/site-packages/django/utils/deprecation.py", line 94, in __call__
    response = response or self.get_response(request)
  File "/home/ubuntu/SuperShop/env/lib/python3.8/site-packages/django/core/handlers/exception.py", line 34, in inner
    response = get_response(request)
  File "/home/ubuntu/SuperShop/env/lib/python3.8/site-packages/django/utils/deprecation.py", line 94, in __call__
    response = response or self.get_response(request)
  File "/home/ubuntu/SuperShop/env/lib/python3.8/site-packages/django/core/handlers/exception.py", line 34, in inner
    response = get_response(request)
  File "/home/ubuntu/SuperShop/env/lib/python3.8/site-packages/django/utils/deprecation.py", line 94, in __call__
    response = response or self.get_response(request)
  File "/home/ubuntu/SuperShop/env/lib/python3.8/site-packages/django/core/handlers/exception.py", line 34, in inner
    response = get_response(request)
> File "/home/ubuntu/SuperShop/env/lib/python3.8/site-packages/django/core/handlers/base.py", line 113, in _get_response
    response = wrapped_callback(request, *callback_args, **callback_kwargs)
  File "/home/ubuntu/SuperShop/shop/views.py", line 27, in product_list
    category = get_object_or_404(Category,
  File "/home/ubuntu/SuperShop/env/lib/python3.8/site-packages/django/shortcuts.py", line 78, in get_object_or_404
    raise Http404('No %s matches the given query.' % queryset.model._meta.object_name)
django.http.response.Http404: No Category matches the given query.
2021-03-30 12:06:08.224 | ERROR    | django.core.handlers.base:_get_response:113 - An error has been caught in function '_get_response', process 'MainProcess' (8254), thread 'Thread-6' (140616222635776):
Traceback (most recent call last):
  File "/home/ubuntu/SuperShop/env/lib/python3.8/site-packages/django/shortcuts.py", line 76, in get_object_or_404
    return queryset.get(*args, **kwargs)
  File "/home/ubuntu/SuperShop/env/lib/python3.8/site-packages/django/db/models/query.py", line 415, in get
    raise self.model.DoesNotExist(
shop.models.Category.DoesNotExist: Category matching query does not exist.

During handling of the above exception, another exception occurred:

Traceback (most recent call last):
  File "/usr/lib/python3.8/threading.py", line 890, in _bootstrap
    self._bootstrap_inner()
  File "/usr/lib/python3.8/threading.py", line 932, in _bootstrap_inner
    self.run()
  File "/usr/lib/python3.8/threading.py", line 870, in run
    self._target(*self._args, **self._kwargs)
  File "/usr/lib/python3.8/socketserver.py", line 650, in process_request_thread
    self.finish_request(request, client_address)
  File "/usr/lib/python3.8/socketserver.py", line 360, in finish_request
    self.RequestHandlerClass(request, client_address, self)
  File "/usr/lib/python3.8/socketserver.py", line 720, in __init__
    self.handle()
  File "/home/ubuntu/SuperShop/env/lib/python3.8/site-packages/django/core/servers/basehttp.py", line 174, in handle
    self.handle_one_request()
  File "/home/ubuntu/SuperShop/env/lib/python3.8/site-packages/django/core/servers/basehttp.py", line 197, in handle_one_request
    handler.run(self.server.get_app())
  File "/usr/lib/python3.8/wsgiref/handlers.py", line 137, in run
    self.result = application(self.environ, self.start_response)
  File "/home/ubuntu/SuperShop/env/lib/python3.8/site-packages/django/contrib/staticfiles/handlers.py", line 68, in __call__
    return self.application(environ, start_response)
  File "/home/ubuntu/SuperShop/env/lib/python3.8/site-packages/django/core/handlers/wsgi.py", line 133, in __call__
    response = self.get_response(request)
  File "/home/ubuntu/SuperShop/env/lib/python3.8/site-packages/django/core/handlers/base.py", line 75, in get_response
    response = self._middleware_chain(request)
  File "/home/ubuntu/SuperShop/env/lib/python3.8/site-packages/django/core/handlers/exception.py", line 34, in inner
    response = get_response(request)
  File "/home/ubuntu/SuperShop/env/lib/python3.8/site-packages/django/utils/deprecation.py", line 94, in __call__
    response = response or self.get_response(request)
  File "/home/ubuntu/SuperShop/env/lib/python3.8/site-packages/django/core/handlers/exception.py", line 34, in inner
    response = get_response(request)
  File "/home/ubuntu/SuperShop/env/lib/python3.8/site-packages/django/utils/deprecation.py", line 94, in __call__
    response = response or self.get_response(request)
  File "/home/ubuntu/SuperShop/env/lib/python3.8/site-packages/django/core/handlers/exception.py", line 34, in inner
    response = get_response(request)
  File "/home/ubuntu/SuperShop/env/lib/python3.8/site-packages/django/utils/deprecation.py", line 94, in __call__
    response = response or self.get_response(request)
  File "/home/ubuntu/SuperShop/env/lib/python3.8/site-packages/django/core/handlers/exception.py", line 34, in inner
    response = get_response(request)
  File "/home/ubuntu/SuperShop/env/lib/python3.8/site-packages/django/utils/deprecation.py", line 94, in __call__
    response = response or self.get_response(request)
  File "/home/ubuntu/SuperShop/env/lib/python3.8/site-packages/django/core/handlers/exception.py", line 34, in inner
    response = get_response(request)
  File "/home/ubuntu/SuperShop/env/lib/python3.8/site-packages/django/utils/deprecation.py", line 94, in __call__
    response = response or self.get_response(request)
  File "/home/ubuntu/SuperShop/env/lib/python3.8/site-packages/django/core/handlers/exception.py", line 34, in inner
    response = get_response(request)
  File "/home/ubuntu/SuperShop/env/lib/python3.8/site-packages/django/utils/deprecation.py", line 94, in __call__
    response = response or self.get_response(request)
  File "/home/ubuntu/SuperShop/env/lib/python3.8/site-packages/django/core/handlers/exception.py", line 34, in inner
    response = get_response(request)
  File "/home/ubuntu/SuperShop/env/lib/python3.8/site-packages/django/utils/deprecation.py", line 94, in __call__
    response = response or self.get_response(request)
  File "/home/ubuntu/SuperShop/env/lib/python3.8/site-packages/django/core/handlers/exception.py", line 34, in inner
    response = get_response(request)
  File "/home/ubuntu/SuperShop/env/lib/python3.8/site-packages/django/utils/deprecation.py", line 94, in __call__
    response = response or self.get_response(request)
  File "/home/ubuntu/SuperShop/env/lib/python3.8/site-packages/django/core/handlers/exception.py", line 34, in inner
    response = get_response(request)
> File "/home/ubuntu/SuperShop/env/lib/python3.8/site-packages/django/core/handlers/base.py", line 113, in _get_response
    response = wrapped_callback(request, *callback_args, **callback_kwargs)
  File "/home/ubuntu/SuperShop/shop/views.py", line 27, in product_list
    category = get_object_or_404(Category,
  File "/home/ubuntu/SuperShop/env/lib/python3.8/site-packages/django/shortcuts.py", line 78, in get_object_or_404
    raise Http404('No %s matches the given query.' % queryset.model._meta.object_name)
django.http.response.Http404: No Category matches the given query.
2021-03-30 14:09:45.426 | ERROR    | django.core.handlers.base:_get_response:113 - An error has been caught in function '_get_response', process 'MainProcess' (2036), thread 'Thread-5' (140596583802624):
Traceback (most recent call last):
  File "/home/ubuntu/SuperShop/env/lib/python3.8/site-packages/django/shortcuts.py", line 76, in get_object_or_404
    return queryset.get(*args, **kwargs)
  File "/home/ubuntu/SuperShop/env/lib/python3.8/site-packages/django/db/models/query.py", line 415, in get
    raise self.model.DoesNotExist(
shop.models.Category.DoesNotExist: Category matching query does not exist.

During handling of the above exception, another exception occurred:

Traceback (most recent call last):
  File "/usr/lib/python3.8/threading.py", line 890, in _bootstrap
    self._bootstrap_inner()
  File "/usr/lib/python3.8/threading.py", line 932, in _bootstrap_inner
    self.run()
  File "/usr/lib/python3.8/threading.py", line 870, in run
    self._target(*self._args, **self._kwargs)
  File "/usr/lib/python3.8/socketserver.py", line 650, in process_request_thread
    self.finish_request(request, client_address)
  File "/usr/lib/python3.8/socketserver.py", line 360, in finish_request
    self.RequestHandlerClass(request, client_address, self)
  File "/usr/lib/python3.8/socketserver.py", line 720, in __init__
    self.handle()
  File "/home/ubuntu/SuperShop/env/lib/python3.8/site-packages/django/core/servers/basehttp.py", line 174, in handle
    self.handle_one_request()
  File "/home/ubuntu/SuperShop/env/lib/python3.8/site-packages/django/core/servers/basehttp.py", line 197, in handle_one_request
    handler.run(self.server.get_app())
  File "/usr/lib/python3.8/wsgiref/handlers.py", line 137, in run
    self.result = application(self.environ, self.start_response)
  File "/home/ubuntu/SuperShop/env/lib/python3.8/site-packages/django/contrib/staticfiles/handlers.py", line 68, in __call__
    return self.application(environ, start_response)
  File "/home/ubuntu/SuperShop/env/lib/python3.8/site-packages/django/core/handlers/wsgi.py", line 133, in __call__
    response = self.get_response(request)
  File "/home/ubuntu/SuperShop/env/lib/python3.8/site-packages/django/core/handlers/base.py", line 75, in get_response
    response = self._middleware_chain(request)
  File "/home/ubuntu/SuperShop/env/lib/python3.8/site-packages/django/core/handlers/exception.py", line 34, in inner
    response = get_response(request)
  File "/home/ubuntu/SuperShop/env/lib/python3.8/site-packages/django/utils/deprecation.py", line 94, in __call__
    response = response or self.get_response(request)
  File "/home/ubuntu/SuperShop/env/lib/python3.8/site-packages/django/core/handlers/exception.py", line 34, in inner
    response = get_response(request)
  File "/home/ubuntu/SuperShop/env/lib/python3.8/site-packages/django/utils/deprecation.py", line 94, in __call__
    response = response or self.get_response(request)
  File "/home/ubuntu/SuperShop/env/lib/python3.8/site-packages/django/core/handlers/exception.py", line 34, in inner
    response = get_response(request)
  File "/home/ubuntu/SuperShop/env/lib/python3.8/site-packages/django/utils/deprecation.py", line 94, in __call__
    response = response or self.get_response(request)
  File "/home/ubuntu/SuperShop/env/lib/python3.8/site-packages/django/core/handlers/exception.py", line 34, in inner
    response = get_response(request)
  File "/home/ubuntu/SuperShop/env/lib/python3.8/site-packages/django/utils/deprecation.py", line 94, in __call__
    response = response or self.get_response(request)
  File "/home/ubuntu/SuperShop/env/lib/python3.8/site-packages/django/core/handlers/exception.py", line 34, in inner
    response = get_response(request)
  File "/home/ubuntu/SuperShop/env/lib/python3.8/site-packages/django/utils/deprecation.py", line 94, in __call__
    response = response or self.get_response(request)
  File "/home/ubuntu/SuperShop/env/lib/python3.8/site-packages/django/core/handlers/exception.py", line 34, in inner
    response = get_response(request)
  File "/home/ubuntu/SuperShop/env/lib/python3.8/site-packages/django/utils/deprecation.py", line 94, in __call__
    response = response or self.get_response(request)
  File "/home/ubuntu/SuperShop/env/lib/python3.8/site-packages/django/core/handlers/exception.py", line 34, in inner
    response = get_response(request)
  File "/home/ubuntu/SuperShop/env/lib/python3.8/site-packages/django/utils/deprecation.py", line 94, in __call__
    response = response or self.get_response(request)
  File "/home/ubuntu/SuperShop/env/lib/python3.8/site-packages/django/core/handlers/exception.py", line 34, in inner
    response = get_response(request)
  File "/home/ubuntu/SuperShop/env/lib/python3.8/site-packages/django/utils/deprecation.py", line 94, in __call__
    response = response or self.get_response(request)
  File "/home/ubuntu/SuperShop/env/lib/python3.8/site-packages/django/core/handlers/exception.py", line 34, in inner
    response = get_response(request)
> File "/home/ubuntu/SuperShop/env/lib/python3.8/site-packages/django/core/handlers/base.py", line 113, in _get_response
    response = wrapped_callback(request, *callback_args, **callback_kwargs)
  File "/home/ubuntu/SuperShop/shop/views.py", line 27, in product_list
    category = get_object_or_404(Category,
  File "/home/ubuntu/SuperShop/env/lib/python3.8/site-packages/django/shortcuts.py", line 78, in get_object_or_404
    raise Http404('No %s matches the given query.' % queryset.model._meta.object_name)
django.http.response.Http404: No Category matches the given query.
2021-03-30 17:09:07.396 | ERROR    | cart.views:cart_detail:50 - An error has been caught in function 'cart_detail', process 'MainProcess' (1828), thread 'Thread-9' (139801777030912):
Traceback (most recent call last):
  File "/home/ubuntu/SuperShop/env/lib/python3.8/site-packages/redis/connection.py", line 552, in connect
    sock = self._connect()
  File "/home/ubuntu/SuperShop/env/lib/python3.8/site-packages/redis/connection.py", line 609, in _connect
    raise err
  File "/home/ubuntu/SuperShop/env/lib/python3.8/site-packages/redis/connection.py", line 597, in _connect
    sock.connect(socket_address)
ConnectionRefusedError: [Errno 111] Connection refused

During handling of the above exception, another exception occurred:

Traceback (most recent call last):
  File "/usr/lib/python3.8/threading.py", line 890, in _bootstrap
    self._bootstrap_inner()
  File "/usr/lib/python3.8/threading.py", line 932, in _bootstrap_inner
    self.run()
  File "/usr/lib/python3.8/threading.py", line 870, in run
    self._target(*self._args, **self._kwargs)
  File "/usr/lib/python3.8/socketserver.py", line 650, in process_request_thread
    self.finish_request(request, client_address)
  File "/usr/lib/python3.8/socketserver.py", line 360, in finish_request
    self.RequestHandlerClass(request, client_address, self)
  File "/usr/lib/python3.8/socketserver.py", line 720, in __init__
    self.handle()
  File "/home/ubuntu/SuperShop/env/lib/python3.8/site-packages/django/core/servers/basehttp.py", line 174, in handle
    self.handle_one_request()
  File "/home/ubuntu/SuperShop/env/lib/python3.8/site-packages/django/core/servers/basehttp.py", line 197, in handle_one_request
    handler.run(self.server.get_app())
  File "/usr/lib/python3.8/wsgiref/handlers.py", line 137, in run
    self.result = application(self.environ, self.start_response)
  File "/home/ubuntu/SuperShop/env/lib/python3.8/site-packages/django/contrib/staticfiles/handlers.py", line 68, in __call__
    return self.application(environ, start_response)
  File "/home/ubuntu/SuperShop/env/lib/python3.8/site-packages/django/core/handlers/wsgi.py", line 133, in __call__
    response = self.get_response(request)
  File "/home/ubuntu/SuperShop/env/lib/python3.8/site-packages/django/core/handlers/base.py", line 75, in get_response
    response = self._middleware_chain(request)
  File "/home/ubuntu/SuperShop/env/lib/python3.8/site-packages/django/core/handlers/exception.py", line 34, in inner
    response = get_response(request)
  File "/home/ubuntu/SuperShop/env/lib/python3.8/site-packages/django/utils/deprecation.py", line 94, in __call__
    response = response or self.get_response(request)
  File "/home/ubuntu/SuperShop/env/lib/python3.8/site-packages/django/core/handlers/exception.py", line 34, in inner
    response = get_response(request)
  File "/home/ubuntu/SuperShop/env/lib/python3.8/site-packages/django/utils/deprecation.py", line 94, in __call__
    response = response or self.get_response(request)
  File "/home/ubuntu/SuperShop/env/lib/python3.8/site-packages/django/core/handlers/exception.py", line 34, in inner
    response = get_response(request)
  File "/home/ubuntu/SuperShop/env/lib/python3.8/site-packages/django/utils/deprecation.py", line 94, in __call__
    response = response or self.get_response(request)
  File "/home/ubuntu/SuperShop/env/lib/python3.8/site-packages/django/core/handlers/exception.py", line 34, in inner
    response = get_response(request)
  File "/home/ubuntu/SuperShop/env/lib/python3.8/site-packages/django/utils/deprecation.py", line 94, in __call__
    response = response or self.get_response(request)
  File "/home/ubuntu/SuperShop/env/lib/python3.8/site-packages/django/core/handlers/exception.py", line 34, in inner
    response = get_response(request)
  File "/home/ubuntu/SuperShop/env/lib/python3.8/site-packages/django/utils/deprecation.py", line 94, in __call__
    response = response or self.get_response(request)
  File "/home/ubuntu/SuperShop/env/lib/python3.8/site-packages/django/core/handlers/exception.py", line 34, in inner
    response = get_response(request)
  File "/home/ubuntu/SuperShop/env/lib/python3.8/site-packages/django/utils/deprecation.py", line 94, in __call__
    response = response or self.get_response(request)
  File "/home/ubuntu/SuperShop/env/lib/python3.8/site-packages/django/core/handlers/exception.py", line 34, in inner
    response = get_response(request)
  File "/home/ubuntu/SuperShop/env/lib/python3.8/site-packages/django/utils/deprecation.py", line 94, in __call__
    response = response or self.get_response(request)
  File "/home/ubuntu/SuperShop/env/lib/python3.8/site-packages/django/core/handlers/exception.py", line 34, in inner
    response = get_response(request)
  File "/home/ubuntu/SuperShop/env/lib/python3.8/site-packages/django/utils/deprecation.py", line 94, in __call__
    response = response or self.get_response(request)
  File "/home/ubuntu/SuperShop/env/lib/python3.8/site-packages/django/core/handlers/exception.py", line 34, in inner
    response = get_response(request)
  File "/home/ubuntu/SuperShop/env/lib/python3.8/site-packages/django/core/handlers/base.py", line 113, in _get_response
    response = wrapped_callback(request, *callback_args, **callback_kwargs)
> File "/home/ubuntu/SuperShop/cart/views.py", line 50, in cart_detail
    recommended_products = r.suggest_products_for(cart_products,
  File "/home/ubuntu/SuperShop/shop/recommender.py", line 41, in suggest_products_for
    suggestions = r.zrange(
  File "/home/ubuntu/SuperShop/env/lib/python3.8/site-packages/redis/client.py", line 2757, in zrange
    return self.zrevrange(name, start, end, withscores,
  File "/home/ubuntu/SuperShop/env/lib/python3.8/site-packages/redis/client.py", line 2884, in zrevrange
    return self.execute_command(*pieces, **options)
  File "/home/ubuntu/SuperShop/env/lib/python3.8/site-packages/redis/client.py", line 875, in execute_command
    conn = self.connection or pool.get_connection(command_name, **options)
  File "/home/ubuntu/SuperShop/env/lib/python3.8/site-packages/redis/connection.py", line 1185, in get_connection
    connection.connect()
  File "/home/ubuntu/SuperShop/env/lib/python3.8/site-packages/redis/connection.py", line 557, in connect
    raise ConnectionError(self._error_message(e))
redis.exceptions.ConnectionError: Error 111 connecting to localhost:6379. Connection refused.
2021-03-31 08:01:32.717 | ERROR    | django.core.handlers.base:_get_response:113 - An error has been caught in function '_get_response', process 'MainProcess' (13672), thread 'MainThread' (139841305081664):
Traceback (most recent call last):
  File "/home/ubuntu/SuperShop/env/lib/python3.8/site-packages/django/shortcuts.py", line 76, in get_object_or_404
    return queryset.get(*args, **kwargs)
  File "/home/ubuntu/SuperShop/env/lib/python3.8/site-packages/django/db/models/query.py", line 415, in get
    raise self.model.DoesNotExist(
orders.models.Order.DoesNotExist: Order matching query does not exist.

During handling of the above exception, another exception occurred:

Traceback (most recent call last):
  File "/home/ubuntu/SuperShop/env/bin/coverage", line 8, in <module>
    sys.exit(main())
  File "/home/ubuntu/SuperShop/env/lib/python3.8/site-packages/coverage/cmdline.py", line 865, in main
    status = CoverageScript().command_line(argv)
  File "/home/ubuntu/SuperShop/env/lib/python3.8/site-packages/coverage/cmdline.py", line 582, in command_line
    return self.do_run(options, args)
  File "/home/ubuntu/SuperShop/env/lib/python3.8/site-packages/coverage/cmdline.py", line 740, in do_run
    runner.run()
  File "/home/ubuntu/SuperShop/env/lib/python3.8/site-packages/coverage/execfile.py", line 247, in run
    exec(code, main_mod.__dict__)
  File "manage.py", line 22, in <module>
    main()
  File "manage.py", line 18, in main
    execute_from_command_line(sys.argv)
  File "/home/ubuntu/SuperShop/env/lib/python3.8/site-packages/django/core/management/__init__.py", line 401, in execute_from_command_line
    utility.execute()
  File "/home/ubuntu/SuperShop/env/lib/python3.8/site-packages/django/core/management/__init__.py", line 395, in execute
    self.fetch_command(subcommand).run_from_argv(self.argv)
  File "/home/ubuntu/SuperShop/env/lib/python3.8/site-packages/django/core/management/commands/test.py", line 23, in run_from_argv
    super().run_from_argv(argv)
  File "/home/ubuntu/SuperShop/env/lib/python3.8/site-packages/django/core/management/base.py", line 328, in run_from_argv
    self.execute(*args, **cmd_options)
  File "/home/ubuntu/SuperShop/env/lib/python3.8/site-packages/django/core/management/base.py", line 369, in execute
    output = self.handle(*args, **options)
  File "/home/ubuntu/SuperShop/env/lib/python3.8/site-packages/django/core/management/commands/test.py", line 53, in handle
    failures = test_runner.run_tests(test_labels)
  File "/home/ubuntu/SuperShop/env/lib/python3.8/site-packages/django/test/runner.py", line 688, in run_tests
    result = self.run_suite(suite)
  File "/home/ubuntu/SuperShop/env/lib/python3.8/site-packages/django/test/runner.py", line 630, in run_suite
    return runner.run(suite)
  File "/usr/lib/python3.8/unittest/runner.py", line 176, in run
    test(result)
  File "/usr/lib/python3.8/unittest/suite.py", line 84, in __call__
    return self.run(*args, **kwds)
  File "/usr/lib/python3.8/unittest/suite.py", line 122, in run
    test(result)
  File "/home/ubuntu/SuperShop/env/lib/python3.8/site-packages/django/test/testcases.py", line 271, in __call__
    super().__call__(result)
  File "/usr/lib/python3.8/unittest/case.py", line 736, in __call__
    return self.run(*args, **kwds)
  File "/usr/lib/python3.8/unittest/case.py", line 676, in run
    self._callTestMethod(testMethod)
  File "/usr/lib/python3.8/unittest/case.py", line 633, in _callTestMethod
    method()
  File "/home/ubuntu/SuperShop/orders/tests/test_urls.py", line 52, in test_admin_order_detail
    response = self.client.get('/en/orders/admin/order/1/')
  File "/home/ubuntu/SuperShop/env/lib/python3.8/site-packages/django/test/client.py", line 518, in get
    response = super().get(path, data=data, secure=secure, **extra)
  File "/home/ubuntu/SuperShop/env/lib/python3.8/site-packages/django/test/client.py", line 344, in get
    return self.generic('GET', path, secure=secure, **{
  File "/home/ubuntu/SuperShop/env/lib/python3.8/site-packages/django/test/client.py", line 421, in generic
    return self.request(**r)
  File "/home/ubuntu/SuperShop/env/lib/python3.8/site-packages/django/test/client.py", line 484, in request
    response = self.handler(environ)
  File "/home/ubuntu/SuperShop/env/lib/python3.8/site-packages/django/test/client.py", line 139, in __call__
    response = self.get_response(request)
  File "/home/ubuntu/SuperShop/env/lib/python3.8/site-packages/django/core/handlers/base.py", line 75, in get_response
    response = self._middleware_chain(request)
  File "/home/ubuntu/SuperShop/env/lib/python3.8/site-packages/django/core/handlers/exception.py", line 34, in inner
    response = get_response(request)
  File "/home/ubuntu/SuperShop/env/lib/python3.8/site-packages/django/utils/deprecation.py", line 94, in __call__
    response = response or self.get_response(request)
  File "/home/ubuntu/SuperShop/env/lib/python3.8/site-packages/django/core/handlers/exception.py", line 34, in inner
    response = get_response(request)
  File "/home/ubuntu/SuperShop/env/lib/python3.8/site-packages/django/utils/deprecation.py", line 94, in __call__
    response = response or self.get_response(request)
  File "/home/ubuntu/SuperShop/env/lib/python3.8/site-packages/django/core/handlers/exception.py", line 34, in inner
    response = get_response(request)
  File "/home/ubuntu/SuperShop/env/lib/python3.8/site-packages/django/utils/deprecation.py", line 94, in __call__
    response = response or self.get_response(request)
  File "/home/ubuntu/SuperShop/env/lib/python3.8/site-packages/django/core/handlers/exception.py", line 34, in inner
    response = get_response(request)
  File "/home/ubuntu/SuperShop/env/lib/python3.8/site-packages/django/utils/deprecation.py", line 94, in __call__
    response = response or self.get_response(request)
  File "/home/ubuntu/SuperShop/env/lib/python3.8/site-packages/django/core/handlers/exception.py", line 34, in inner
    response = get_response(request)
  File "/home/ubuntu/SuperShop/env/lib/python3.8/site-packages/django/utils/deprecation.py", line 94, in __call__
    response = response or self.get_response(request)
  File "/home/ubuntu/SuperShop/env/lib/python3.8/site-packages/django/core/handlers/exception.py", line 34, in inner
    response = get_response(request)
  File "/home/ubuntu/SuperShop/env/lib/python3.8/site-packages/django/utils/deprecation.py", line 94, in __call__
    response = response or self.get_response(request)
  File "/home/ubuntu/SuperShop/env/lib/python3.8/site-packages/django/core/handlers/exception.py", line 34, in inner
    response = get_response(request)
  File "/home/ubuntu/SuperShop/env/lib/python3.8/site-packages/django/utils/deprecation.py", line 94, in __call__
    response = response or self.get_response(request)
  File "/home/ubuntu/SuperShop/env/lib/python3.8/site-packages/django/core/handlers/exception.py", line 34, in inner
    response = get_response(request)
  File "/home/ubuntu/SuperShop/env/lib/python3.8/site-packages/django/utils/deprecation.py", line 94, in __call__
    response = response or self.get_response(request)
  File "/home/ubuntu/SuperShop/env/lib/python3.8/site-packages/django/core/handlers/exception.py", line 34, in inner
    response = get_response(request)
> File "/home/ubuntu/SuperShop/env/lib/python3.8/site-packages/django/core/handlers/base.py", line 113, in _get_response
    response = wrapped_callback(request, *callback_args, **callback_kwargs)
  File "/home/ubuntu/SuperShop/env/lib/python3.8/site-packages/django/contrib/auth/decorators.py", line 21, in _wrapped_view
    return view_func(request, *args, **kwargs)
  File "/home/ubuntu/SuperShop/orders/views.py", line 51, in admin_order_detail
    order = get_object_or_404(Order, id=order_id)
  File "/home/ubuntu/SuperShop/env/lib/python3.8/site-packages/django/shortcuts.py", line 78, in get_object_or_404
    raise Http404('No %s matches the given query.' % queryset.model._meta.object_name)
django.http.response.Http404: No Order matches the given query.
2021-03-31 08:01:33.066 | ERROR    | django.core.handlers.base:_get_response:113 - An error has been caught in function '_get_response', process 'MainProcess' (13672), thread 'MainThread' (139841305081664):
Traceback (most recent call last):
  File "/home/ubuntu/SuperShop/env/lib/python3.8/site-packages/django/shortcuts.py", line 76, in get_object_or_404
    return queryset.get(*args, **kwargs)
  File "/home/ubuntu/SuperShop/env/lib/python3.8/site-packages/django/db/models/query.py", line 415, in get
    raise self.model.DoesNotExist(
orders.models.Order.DoesNotExist: Order matching query does not exist.

During handling of the above exception, another exception occurred:

Traceback (most recent call last):
  File "/home/ubuntu/SuperShop/env/bin/coverage", line 8, in <module>
    sys.exit(main())
  File "/home/ubuntu/SuperShop/env/lib/python3.8/site-packages/coverage/cmdline.py", line 865, in main
    status = CoverageScript().command_line(argv)
  File "/home/ubuntu/SuperShop/env/lib/python3.8/site-packages/coverage/cmdline.py", line 582, in command_line
    return self.do_run(options, args)
  File "/home/ubuntu/SuperShop/env/lib/python3.8/site-packages/coverage/cmdline.py", line 740, in do_run
    runner.run()
  File "/home/ubuntu/SuperShop/env/lib/python3.8/site-packages/coverage/execfile.py", line 247, in run
    exec(code, main_mod.__dict__)
  File "manage.py", line 22, in <module>
    main()
  File "manage.py", line 18, in main
    execute_from_command_line(sys.argv)
  File "/home/ubuntu/SuperShop/env/lib/python3.8/site-packages/django/core/management/__init__.py", line 401, in execute_from_command_line
    utility.execute()
  File "/home/ubuntu/SuperShop/env/lib/python3.8/site-packages/django/core/management/__init__.py", line 395, in execute
    self.fetch_command(subcommand).run_from_argv(self.argv)
  File "/home/ubuntu/SuperShop/env/lib/python3.8/site-packages/django/core/management/commands/test.py", line 23, in run_from_argv
    super().run_from_argv(argv)
  File "/home/ubuntu/SuperShop/env/lib/python3.8/site-packages/django/core/management/base.py", line 328, in run_from_argv
    self.execute(*args, **cmd_options)
  File "/home/ubuntu/SuperShop/env/lib/python3.8/site-packages/django/core/management/base.py", line 369, in execute
    output = self.handle(*args, **options)
  File "/home/ubuntu/SuperShop/env/lib/python3.8/site-packages/django/core/management/commands/test.py", line 53, in handle
    failures = test_runner.run_tests(test_labels)
  File "/home/ubuntu/SuperShop/env/lib/python3.8/site-packages/django/test/runner.py", line 688, in run_tests
    result = self.run_suite(suite)
  File "/home/ubuntu/SuperShop/env/lib/python3.8/site-packages/django/test/runner.py", line 630, in run_suite
    return runner.run(suite)
  File "/usr/lib/python3.8/unittest/runner.py", line 176, in run
    test(result)
  File "/usr/lib/python3.8/unittest/suite.py", line 84, in __call__
    return self.run(*args, **kwds)
  File "/usr/lib/python3.8/unittest/suite.py", line 122, in run
    test(result)
  File "/home/ubuntu/SuperShop/env/lib/python3.8/site-packages/django/test/testcases.py", line 271, in __call__
    super().__call__(result)
  File "/usr/lib/python3.8/unittest/case.py", line 736, in __call__
    return self.run(*args, **kwds)
  File "/usr/lib/python3.8/unittest/case.py", line 676, in run
    self._callTestMethod(testMethod)
  File "/usr/lib/python3.8/unittest/case.py", line 633, in _callTestMethod
    method()
  File "/home/ubuntu/SuperShop/orders/tests/test_urls.py", line 75, in test_admin_order_PDF
    response = self.client.get('/en/orders/admin/order/1/pdf/')
  File "/home/ubuntu/SuperShop/env/lib/python3.8/site-packages/django/test/client.py", line 518, in get
    response = super().get(path, data=data, secure=secure, **extra)
  File "/home/ubuntu/SuperShop/env/lib/python3.8/site-packages/django/test/client.py", line 344, in get
    return self.generic('GET', path, secure=secure, **{
  File "/home/ubuntu/SuperShop/env/lib/python3.8/site-packages/django/test/client.py", line 421, in generic
    return self.request(**r)
  File "/home/ubuntu/SuperShop/env/lib/python3.8/site-packages/django/test/client.py", line 484, in request
    response = self.handler(environ)
  File "/home/ubuntu/SuperShop/env/lib/python3.8/site-packages/django/test/client.py", line 139, in __call__
    response = self.get_response(request)
  File "/home/ubuntu/SuperShop/env/lib/python3.8/site-packages/django/core/handlers/base.py", line 75, in get_response
    response = self._middleware_chain(request)
  File "/home/ubuntu/SuperShop/env/lib/python3.8/site-packages/django/core/handlers/exception.py", line 34, in inner
    response = get_response(request)
  File "/home/ubuntu/SuperShop/env/lib/python3.8/site-packages/django/utils/deprecation.py", line 94, in __call__
    response = response or self.get_response(request)
  File "/home/ubuntu/SuperShop/env/lib/python3.8/site-packages/django/core/handlers/exception.py", line 34, in inner
    response = get_response(request)
  File "/home/ubuntu/SuperShop/env/lib/python3.8/site-packages/django/utils/deprecation.py", line 94, in __call__
    response = response or self.get_response(request)
  File "/home/ubuntu/SuperShop/env/lib/python3.8/site-packages/django/core/handlers/exception.py", line 34, in inner
    response = get_response(request)
  File "/home/ubuntu/SuperShop/env/lib/python3.8/site-packages/django/utils/deprecation.py", line 94, in __call__
    response = response or self.get_response(request)
  File "/home/ubuntu/SuperShop/env/lib/python3.8/site-packages/django/core/handlers/exception.py", line 34, in inner
    response = get_response(request)
  File "/home/ubuntu/SuperShop/env/lib/python3.8/site-packages/django/utils/deprecation.py", line 94, in __call__
    response = response or self.get_response(request)
  File "/home/ubuntu/SuperShop/env/lib/python3.8/site-packages/django/core/handlers/exception.py", line 34, in inner
    response = get_response(request)
  File "/home/ubuntu/SuperShop/env/lib/python3.8/site-packages/django/utils/deprecation.py", line 94, in __call__
    response = response or self.get_response(request)
  File "/home/ubuntu/SuperShop/env/lib/python3.8/site-packages/django/core/handlers/exception.py", line 34, in inner
    response = get_response(request)
  File "/home/ubuntu/SuperShop/env/lib/python3.8/site-packages/django/utils/deprecation.py", line 94, in __call__
    response = response or self.get_response(request)
  File "/home/ubuntu/SuperShop/env/lib/python3.8/site-packages/django/core/handlers/exception.py", line 34, in inner
    response = get_response(request)
  File "/home/ubuntu/SuperShop/env/lib/python3.8/site-packages/django/utils/deprecation.py", line 94, in __call__
    response = response or self.get_response(request)
  File "/home/ubuntu/SuperShop/env/lib/python3.8/site-packages/django/core/handlers/exception.py", line 34, in inner
    response = get_response(request)
  File "/home/ubuntu/SuperShop/env/lib/python3.8/site-packages/django/utils/deprecation.py", line 94, in __call__
    response = response or self.get_response(request)
  File "/home/ubuntu/SuperShop/env/lib/python3.8/site-packages/django/core/handlers/exception.py", line 34, in inner
    response = get_response(request)
> File "/home/ubuntu/SuperShop/env/lib/python3.8/site-packages/django/core/handlers/base.py", line 113, in _get_response
    response = wrapped_callback(request, *callback_args, **callback_kwargs)
  File "/home/ubuntu/SuperShop/env/lib/python3.8/site-packages/django/contrib/auth/decorators.py", line 21, in _wrapped_view
    return view_func(request, *args, **kwargs)
  File "/home/ubuntu/SuperShop/orders/views.py", line 59, in admin_order_pdf
    order = get_object_or_404(Order, id=order_id)
  File "/home/ubuntu/SuperShop/env/lib/python3.8/site-packages/django/shortcuts.py", line 78, in get_object_or_404
    raise Http404('No %s matches the given query.' % queryset.model._meta.object_name)
django.http.response.Http404: No Order matches the given query.
2021-03-31 08:01:34.547 | ERROR    | django.core.handlers.base:_get_response:113 - An error has been caught in function '_get_response', process 'MainProcess' (13672), thread 'MainThread' (139841305081664):
Traceback (most recent call last):
  File "/home/ubuntu/SuperShop/env/lib/python3.8/site-packages/django/shortcuts.py", line 76, in get_object_or_404
    return queryset.get(*args, **kwargs)
  File "/home/ubuntu/SuperShop/env/lib/python3.8/site-packages/django/db/models/query.py", line 415, in get
    raise self.model.DoesNotExist(
orders.models.Order.DoesNotExist: Order matching query does not exist.

During handling of the above exception, another exception occurred:

Traceback (most recent call last):
  File "/home/ubuntu/SuperShop/env/bin/coverage", line 8, in <module>
    sys.exit(main())
  File "/home/ubuntu/SuperShop/env/lib/python3.8/site-packages/coverage/cmdline.py", line 865, in main
    status = CoverageScript().command_line(argv)
  File "/home/ubuntu/SuperShop/env/lib/python3.8/site-packages/coverage/cmdline.py", line 582, in command_line
    return self.do_run(options, args)
  File "/home/ubuntu/SuperShop/env/lib/python3.8/site-packages/coverage/cmdline.py", line 740, in do_run
    runner.run()
  File "/home/ubuntu/SuperShop/env/lib/python3.8/site-packages/coverage/execfile.py", line 247, in run
    exec(code, main_mod.__dict__)
  File "manage.py", line 22, in <module>
    main()
  File "manage.py", line 18, in main
    execute_from_command_line(sys.argv)
  File "/home/ubuntu/SuperShop/env/lib/python3.8/site-packages/django/core/management/__init__.py", line 401, in execute_from_command_line
    utility.execute()
  File "/home/ubuntu/SuperShop/env/lib/python3.8/site-packages/django/core/management/__init__.py", line 395, in execute
    self.fetch_command(subcommand).run_from_argv(self.argv)
  File "/home/ubuntu/SuperShop/env/lib/python3.8/site-packages/django/core/management/commands/test.py", line 23, in run_from_argv
    super().run_from_argv(argv)
  File "/home/ubuntu/SuperShop/env/lib/python3.8/site-packages/django/core/management/base.py", line 328, in run_from_argv
    self.execute(*args, **cmd_options)
  File "/home/ubuntu/SuperShop/env/lib/python3.8/site-packages/django/core/management/base.py", line 369, in execute
    output = self.handle(*args, **options)
  File "/home/ubuntu/SuperShop/env/lib/python3.8/site-packages/django/core/management/commands/test.py", line 53, in handle
    failures = test_runner.run_tests(test_labels)
  File "/home/ubuntu/SuperShop/env/lib/python3.8/site-packages/django/test/runner.py", line 688, in run_tests
    result = self.run_suite(suite)
  File "/home/ubuntu/SuperShop/env/lib/python3.8/site-packages/django/test/runner.py", line 630, in run_suite
    return runner.run(suite)
  File "/usr/lib/python3.8/unittest/runner.py", line 176, in run
    test(result)
  File "/usr/lib/python3.8/unittest/suite.py", line 84, in __call__
    return self.run(*args, **kwds)
  File "/usr/lib/python3.8/unittest/suite.py", line 122, in run
    test(result)
  File "/home/ubuntu/SuperShop/env/lib/python3.8/site-packages/django/test/testcases.py", line 271, in __call__
    super().__call__(result)
  File "/usr/lib/python3.8/unittest/case.py", line 736, in __call__
    return self.run(*args, **kwds)
  File "/usr/lib/python3.8/unittest/case.py", line 676, in run
    self._callTestMethod(testMethod)
  File "/usr/lib/python3.8/unittest/case.py", line 633, in _callTestMethod
    method()
  File "/home/ubuntu/SuperShop/orders/tests/test_urls.py", line 133, in test_order_detail
    response = self.client.get('/en/orders/order_detail/1/')
  File "/home/ubuntu/SuperShop/env/lib/python3.8/site-packages/django/test/client.py", line 518, in get
    response = super().get(path, data=data, secure=secure, **extra)
  File "/home/ubuntu/SuperShop/env/lib/python3.8/site-packages/django/test/client.py", line 344, in get
    return self.generic('GET', path, secure=secure, **{
  File "/home/ubuntu/SuperShop/env/lib/python3.8/site-packages/django/test/client.py", line 421, in generic
    return self.request(**r)
  File "/home/ubuntu/SuperShop/env/lib/python3.8/site-packages/django/test/client.py", line 484, in request
    response = self.handler(environ)
  File "/home/ubuntu/SuperShop/env/lib/python3.8/site-packages/django/test/client.py", line 139, in __call__
    response = self.get_response(request)
  File "/home/ubuntu/SuperShop/env/lib/python3.8/site-packages/django/core/handlers/base.py", line 75, in get_response
    response = self._middleware_chain(request)
  File "/home/ubuntu/SuperShop/env/lib/python3.8/site-packages/django/core/handlers/exception.py", line 34, in inner
    response = get_response(request)
  File "/home/ubuntu/SuperShop/env/lib/python3.8/site-packages/django/utils/deprecation.py", line 94, in __call__
    response = response or self.get_response(request)
  File "/home/ubuntu/SuperShop/env/lib/python3.8/site-packages/django/core/handlers/exception.py", line 34, in inner
    response = get_response(request)
  File "/home/ubuntu/SuperShop/env/lib/python3.8/site-packages/django/utils/deprecation.py", line 94, in __call__
    response = response or self.get_response(request)
  File "/home/ubuntu/SuperShop/env/lib/python3.8/site-packages/django/core/handlers/exception.py", line 34, in inner
    response = get_response(request)
  File "/home/ubuntu/SuperShop/env/lib/python3.8/site-packages/django/utils/deprecation.py", line 94, in __call__
    response = response or self.get_response(request)
  File "/home/ubuntu/SuperShop/env/lib/python3.8/site-packages/django/core/handlers/exception.py", line 34, in inner
    response = get_response(request)
  File "/home/ubuntu/SuperShop/env/lib/python3.8/site-packages/django/utils/deprecation.py", line 94, in __call__
    response = response or self.get_response(request)
  File "/home/ubuntu/SuperShop/env/lib/python3.8/site-packages/django/core/handlers/exception.py", line 34, in inner
    response = get_response(request)
  File "/home/ubuntu/SuperShop/env/lib/python3.8/site-packages/django/utils/deprecation.py", line 94, in __call__
    response = response or self.get_response(request)
  File "/home/ubuntu/SuperShop/env/lib/python3.8/site-packages/django/core/handlers/exception.py", line 34, in inner
    response = get_response(request)
  File "/home/ubuntu/SuperShop/env/lib/python3.8/site-packages/django/utils/deprecation.py", line 94, in __call__
    response = response or self.get_response(request)
  File "/home/ubuntu/SuperShop/env/lib/python3.8/site-packages/django/core/handlers/exception.py", line 34, in inner
    response = get_response(request)
  File "/home/ubuntu/SuperShop/env/lib/python3.8/site-packages/django/utils/deprecation.py", line 94, in __call__
    response = response or self.get_response(request)
  File "/home/ubuntu/SuperShop/env/lib/python3.8/site-packages/django/core/handlers/exception.py", line 34, in inner
    response = get_response(request)
  File "/home/ubuntu/SuperShop/env/lib/python3.8/site-packages/django/utils/deprecation.py", line 94, in __call__
    response = response or self.get_response(request)
  File "/home/ubuntu/SuperShop/env/lib/python3.8/site-packages/django/core/handlers/exception.py", line 34, in inner
    response = get_response(request)
> File "/home/ubuntu/SuperShop/env/lib/python3.8/site-packages/django/core/handlers/base.py", line 113, in _get_response
    response = wrapped_callback(request, *callback_args, **callback_kwargs)
  File "/home/ubuntu/SuperShop/env/lib/python3.8/site-packages/django/contrib/auth/decorators.py", line 21, in _wrapped_view
    return view_func(request, *args, **kwargs)
  File "/home/ubuntu/SuperShop/orders/views.py", line 81, in order_detail
    order = get_object_or_404(Order, id=order_id)
  File "/home/ubuntu/SuperShop/env/lib/python3.8/site-packages/django/shortcuts.py", line 78, in get_object_or_404
    raise Http404('No %s matches the given query.' % queryset.model._meta.object_name)
django.http.response.Http404: No Order matches the given query.
2021-03-31 08:01:38.577 | ERROR    | django.core.handlers.base:_get_response:113 - An error has been caught in function '_get_response', process 'MainProcess' (13672), thread 'MainThread' (139841305081664):
Traceback (most recent call last):
  File "/home/ubuntu/SuperShop/env/lib/python3.8/site-packages/django/shortcuts.py", line 76, in get_object_or_404
    return queryset.get(*args, **kwargs)
  File "/home/ubuntu/SuperShop/env/lib/python3.8/site-packages/django/db/models/query.py", line 415, in get
    raise self.model.DoesNotExist(
shop.models.Product.DoesNotExist: Product matching query does not exist.

During handling of the above exception, another exception occurred:

Traceback (most recent call last):
  File "/home/ubuntu/SuperShop/env/bin/coverage", line 8, in <module>
    sys.exit(main())
  File "/home/ubuntu/SuperShop/env/lib/python3.8/site-packages/coverage/cmdline.py", line 865, in main
    status = CoverageScript().command_line(argv)
  File "/home/ubuntu/SuperShop/env/lib/python3.8/site-packages/coverage/cmdline.py", line 582, in command_line
    return self.do_run(options, args)
  File "/home/ubuntu/SuperShop/env/lib/python3.8/site-packages/coverage/cmdline.py", line 740, in do_run
    runner.run()
  File "/home/ubuntu/SuperShop/env/lib/python3.8/site-packages/coverage/execfile.py", line 247, in run
    exec(code, main_mod.__dict__)
  File "manage.py", line 22, in <module>
    main()
  File "manage.py", line 18, in main
    execute_from_command_line(sys.argv)
  File "/home/ubuntu/SuperShop/env/lib/python3.8/site-packages/django/core/management/__init__.py", line 401, in execute_from_command_line
    utility.execute()
  File "/home/ubuntu/SuperShop/env/lib/python3.8/site-packages/django/core/management/__init__.py", line 395, in execute
    self.fetch_command(subcommand).run_from_argv(self.argv)
  File "/home/ubuntu/SuperShop/env/lib/python3.8/site-packages/django/core/management/commands/test.py", line 23, in run_from_argv
    super().run_from_argv(argv)
  File "/home/ubuntu/SuperShop/env/lib/python3.8/site-packages/django/core/management/base.py", line 328, in run_from_argv
    self.execute(*args, **cmd_options)
  File "/home/ubuntu/SuperShop/env/lib/python3.8/site-packages/django/core/management/base.py", line 369, in execute
    output = self.handle(*args, **options)
  File "/home/ubuntu/SuperShop/env/lib/python3.8/site-packages/django/core/management/commands/test.py", line 53, in handle
    failures = test_runner.run_tests(test_labels)
  File "/home/ubuntu/SuperShop/env/lib/python3.8/site-packages/django/test/runner.py", line 688, in run_tests
    result = self.run_suite(suite)
  File "/home/ubuntu/SuperShop/env/lib/python3.8/site-packages/django/test/runner.py", line 630, in run_suite
    return runner.run(suite)
  File "/usr/lib/python3.8/unittest/runner.py", line 176, in run
    test(result)
  File "/usr/lib/python3.8/unittest/suite.py", line 84, in __call__
    return self.run(*args, **kwds)
  File "/usr/lib/python3.8/unittest/suite.py", line 122, in run
    test(result)
  File "/home/ubuntu/SuperShop/env/lib/python3.8/site-packages/django/test/testcases.py", line 271, in __call__
    super().__call__(result)
  File "/usr/lib/python3.8/unittest/case.py", line 736, in __call__
    return self.run(*args, **kwds)
  File "/usr/lib/python3.8/unittest/case.py", line 676, in run
    self._callTestMethod(testMethod)
  File "/usr/lib/python3.8/unittest/case.py", line 633, in _callTestMethod
    method()
  File "/home/ubuntu/SuperShop/shop/tests/test_views.py", line 129, in test_product_detail_view
    no_response = self.client.get('/en/12/no-banana/')
  File "/home/ubuntu/SuperShop/env/lib/python3.8/site-packages/django/test/client.py", line 518, in get
    response = super().get(path, data=data, secure=secure, **extra)
  File "/home/ubuntu/SuperShop/env/lib/python3.8/site-packages/django/test/client.py", line 344, in get
    return self.generic('GET', path, secure=secure, **{
  File "/home/ubuntu/SuperShop/env/lib/python3.8/site-packages/django/test/client.py", line 421, in generic
    return self.request(**r)
  File "/home/ubuntu/SuperShop/env/lib/python3.8/site-packages/django/test/client.py", line 484, in request
    response = self.handler(environ)
  File "/home/ubuntu/SuperShop/env/lib/python3.8/site-packages/django/test/client.py", line 139, in __call__
    response = self.get_response(request)
  File "/home/ubuntu/SuperShop/env/lib/python3.8/site-packages/django/core/handlers/base.py", line 75, in get_response
    response = self._middleware_chain(request)
  File "/home/ubuntu/SuperShop/env/lib/python3.8/site-packages/django/core/handlers/exception.py", line 34, in inner
    response = get_response(request)
  File "/home/ubuntu/SuperShop/env/lib/python3.8/site-packages/django/utils/deprecation.py", line 94, in __call__
    response = response or self.get_response(request)
  File "/home/ubuntu/SuperShop/env/lib/python3.8/site-packages/django/core/handlers/exception.py", line 34, in inner
    response = get_response(request)
  File "/home/ubuntu/SuperShop/env/lib/python3.8/site-packages/django/utils/deprecation.py", line 94, in __call__
    response = response or self.get_response(request)
  File "/home/ubuntu/SuperShop/env/lib/python3.8/site-packages/django/core/handlers/exception.py", line 34, in inner
    response = get_response(request)
  File "/home/ubuntu/SuperShop/env/lib/python3.8/site-packages/django/utils/deprecation.py", line 94, in __call__
    response = response or self.get_response(request)
  File "/home/ubuntu/SuperShop/env/lib/python3.8/site-packages/django/core/handlers/exception.py", line 34, in inner
    response = get_response(request)
  File "/home/ubuntu/SuperShop/env/lib/python3.8/site-packages/django/utils/deprecation.py", line 94, in __call__
    response = response or self.get_response(request)
  File "/home/ubuntu/SuperShop/env/lib/python3.8/site-packages/django/core/handlers/exception.py", line 34, in inner
    response = get_response(request)
  File "/home/ubuntu/SuperShop/env/lib/python3.8/site-packages/django/utils/deprecation.py", line 94, in __call__
    response = response or self.get_response(request)
  File "/home/ubuntu/SuperShop/env/lib/python3.8/site-packages/django/core/handlers/exception.py", line 34, in inner
    response = get_response(request)
  File "/home/ubuntu/SuperShop/env/lib/python3.8/site-packages/django/utils/deprecation.py", line 94, in __call__
    response = response or self.get_response(request)
  File "/home/ubuntu/SuperShop/env/lib/python3.8/site-packages/django/core/handlers/exception.py", line 34, in inner
    response = get_response(request)
  File "/home/ubuntu/SuperShop/env/lib/python3.8/site-packages/django/utils/deprecation.py", line 94, in __call__
    response = response or self.get_response(request)
  File "/home/ubuntu/SuperShop/env/lib/python3.8/site-packages/django/core/handlers/exception.py", line 34, in inner
    response = get_response(request)
  File "/home/ubuntu/SuperShop/env/lib/python3.8/site-packages/django/utils/deprecation.py", line 94, in __call__
    response = response or self.get_response(request)
  File "/home/ubuntu/SuperShop/env/lib/python3.8/site-packages/django/core/handlers/exception.py", line 34, in inner
    response = get_response(request)
> File "/home/ubuntu/SuperShop/env/lib/python3.8/site-packages/django/core/handlers/base.py", line 113, in _get_response
    response = wrapped_callback(request, *callback_args, **callback_kwargs)
  File "/home/ubuntu/SuperShop/shop/views.py", line 56, in product_detail
    product = get_object_or_404(Product,
  File "/home/ubuntu/SuperShop/env/lib/python3.8/site-packages/django/shortcuts.py", line 78, in get_object_or_404
    raise Http404('No %s matches the given query.' % queryset.model._meta.object_name)
django.http.response.Http404: No Product matches the given query.
2021-03-31 08:02:56.036 | ERROR    | django.core.handlers.base:_get_response:113 - An error has been caught in function '_get_response', process 'MainProcess' (14453), thread 'MainThread' (139663680321344):
Traceback (most recent call last):
  File "/home/ubuntu/SuperShop/env/lib/python3.8/site-packages/django/shortcuts.py", line 76, in get_object_or_404
    return queryset.get(*args, **kwargs)
  File "/home/ubuntu/SuperShop/env/lib/python3.8/site-packages/django/db/models/query.py", line 415, in get
    raise self.model.DoesNotExist(
shop.models.Product.DoesNotExist: Product matching query does not exist.

During handling of the above exception, another exception occurred:

Traceback (most recent call last):
  File "/home/ubuntu/SuperShop/env/bin/coverage", line 8, in <module>
    sys.exit(main())
  File "/home/ubuntu/SuperShop/env/lib/python3.8/site-packages/coverage/cmdline.py", line 865, in main
    status = CoverageScript().command_line(argv)
  File "/home/ubuntu/SuperShop/env/lib/python3.8/site-packages/coverage/cmdline.py", line 582, in command_line
    return self.do_run(options, args)
  File "/home/ubuntu/SuperShop/env/lib/python3.8/site-packages/coverage/cmdline.py", line 740, in do_run
    runner.run()
  File "/home/ubuntu/SuperShop/env/lib/python3.8/site-packages/coverage/execfile.py", line 247, in run
    exec(code, main_mod.__dict__)
  File "manage.py", line 22, in <module>
    main()
  File "manage.py", line 18, in main
    execute_from_command_line(sys.argv)
  File "/home/ubuntu/SuperShop/env/lib/python3.8/site-packages/django/core/management/__init__.py", line 401, in execute_from_command_line
    utility.execute()
  File "/home/ubuntu/SuperShop/env/lib/python3.8/site-packages/django/core/management/__init__.py", line 395, in execute
    self.fetch_command(subcommand).run_from_argv(self.argv)
  File "/home/ubuntu/SuperShop/env/lib/python3.8/site-packages/django/core/management/commands/test.py", line 23, in run_from_argv
    super().run_from_argv(argv)
  File "/home/ubuntu/SuperShop/env/lib/python3.8/site-packages/django/core/management/base.py", line 328, in run_from_argv
    self.execute(*args, **cmd_options)
  File "/home/ubuntu/SuperShop/env/lib/python3.8/site-packages/django/core/management/base.py", line 369, in execute
    output = self.handle(*args, **options)
  File "/home/ubuntu/SuperShop/env/lib/python3.8/site-packages/django/core/management/commands/test.py", line 53, in handle
    failures = test_runner.run_tests(test_labels)
  File "/home/ubuntu/SuperShop/env/lib/python3.8/site-packages/django/test/runner.py", line 688, in run_tests
    result = self.run_suite(suite)
  File "/home/ubuntu/SuperShop/env/lib/python3.8/site-packages/django/test/runner.py", line 630, in run_suite
    return runner.run(suite)
  File "/usr/lib/python3.8/unittest/runner.py", line 176, in run
    test(result)
  File "/usr/lib/python3.8/unittest/suite.py", line 84, in __call__
    return self.run(*args, **kwds)
  File "/usr/lib/python3.8/unittest/suite.py", line 122, in run
    test(result)
  File "/home/ubuntu/SuperShop/env/lib/python3.8/site-packages/django/test/testcases.py", line 271, in __call__
    super().__call__(result)
  File "/usr/lib/python3.8/unittest/case.py", line 736, in __call__
    return self.run(*args, **kwds)
  File "/usr/lib/python3.8/unittest/case.py", line 676, in run
    self._callTestMethod(testMethod)
  File "/usr/lib/python3.8/unittest/case.py", line 633, in _callTestMethod
    method()
  File "/home/ubuntu/SuperShop/shop/tests/test_views.py", line 129, in test_product_detail_view
    no_response = self.client.get('/en/12/no-banana/')
  File "/home/ubuntu/SuperShop/env/lib/python3.8/site-packages/django/test/client.py", line 518, in get
    response = super().get(path, data=data, secure=secure, **extra)
  File "/home/ubuntu/SuperShop/env/lib/python3.8/site-packages/django/test/client.py", line 344, in get
    return self.generic('GET', path, secure=secure, **{
  File "/home/ubuntu/SuperShop/env/lib/python3.8/site-packages/django/test/client.py", line 421, in generic
    return self.request(**r)
  File "/home/ubuntu/SuperShop/env/lib/python3.8/site-packages/django/test/client.py", line 484, in request
    response = self.handler(environ)
  File "/home/ubuntu/SuperShop/env/lib/python3.8/site-packages/django/test/client.py", line 139, in __call__
    response = self.get_response(request)
  File "/home/ubuntu/SuperShop/env/lib/python3.8/site-packages/django/core/handlers/base.py", line 75, in get_response
    response = self._middleware_chain(request)
  File "/home/ubuntu/SuperShop/env/lib/python3.8/site-packages/django/core/handlers/exception.py", line 34, in inner
    response = get_response(request)
  File "/home/ubuntu/SuperShop/env/lib/python3.8/site-packages/django/utils/deprecation.py", line 94, in __call__
    response = response or self.get_response(request)
  File "/home/ubuntu/SuperShop/env/lib/python3.8/site-packages/django/core/handlers/exception.py", line 34, in inner
    response = get_response(request)
  File "/home/ubuntu/SuperShop/env/lib/python3.8/site-packages/django/utils/deprecation.py", line 94, in __call__
    response = response or self.get_response(request)
  File "/home/ubuntu/SuperShop/env/lib/python3.8/site-packages/django/core/handlers/exception.py", line 34, in inner
    response = get_response(request)
  File "/home/ubuntu/SuperShop/env/lib/python3.8/site-packages/django/utils/deprecation.py", line 94, in __call__
    response = response or self.get_response(request)
  File "/home/ubuntu/SuperShop/env/lib/python3.8/site-packages/django/core/handlers/exception.py", line 34, in inner
    response = get_response(request)
  File "/home/ubuntu/SuperShop/env/lib/python3.8/site-packages/django/utils/deprecation.py", line 94, in __call__
    response = response or self.get_response(request)
  File "/home/ubuntu/SuperShop/env/lib/python3.8/site-packages/django/core/handlers/exception.py", line 34, in inner
    response = get_response(request)
  File "/home/ubuntu/SuperShop/env/lib/python3.8/site-packages/django/utils/deprecation.py", line 94, in __call__
    response = response or self.get_response(request)
  File "/home/ubuntu/SuperShop/env/lib/python3.8/site-packages/django/core/handlers/exception.py", line 34, in inner
    response = get_response(request)
  File "/home/ubuntu/SuperShop/env/lib/python3.8/site-packages/django/utils/deprecation.py", line 94, in __call__
    response = response or self.get_response(request)
  File "/home/ubuntu/SuperShop/env/lib/python3.8/site-packages/django/core/handlers/exception.py", line 34, in inner
    response = get_response(request)
  File "/home/ubuntu/SuperShop/env/lib/python3.8/site-packages/django/utils/deprecation.py", line 94, in __call__
    response = response or self.get_response(request)
  File "/home/ubuntu/SuperShop/env/lib/python3.8/site-packages/django/core/handlers/exception.py", line 34, in inner
    response = get_response(request)
  File "/home/ubuntu/SuperShop/env/lib/python3.8/site-packages/django/utils/deprecation.py", line 94, in __call__
    response = response or self.get_response(request)
  File "/home/ubuntu/SuperShop/env/lib/python3.8/site-packages/django/core/handlers/exception.py", line 34, in inner
    response = get_response(request)
> File "/home/ubuntu/SuperShop/env/lib/python3.8/site-packages/django/core/handlers/base.py", line 113, in _get_response
    response = wrapped_callback(request, *callback_args, **callback_kwargs)
  File "/home/ubuntu/SuperShop/shop/views.py", line 56, in product_detail
    product = get_object_or_404(Product,
  File "/home/ubuntu/SuperShop/env/lib/python3.8/site-packages/django/shortcuts.py", line 78, in get_object_or_404
    raise Http404('No %s matches the given query.' % queryset.model._meta.object_name)
django.http.response.Http404: No Product matches the given query.
